Workbook

Sheet 안내
A1: 이 워크북 읽는 법
A2: 실제 원시데이터가 없는 상태에서 업계 표준·공공기관·제조사 자료를 근거로 만든 예상안입니다. 수치는 출처 기준이며 설비 사양이 정해지면 다시 확인해야 합니다. 제2판(2026-09-17)에서 실제 사업 도면(가평 2MW 청정수소발전 P&ID, FCND-GP-PID-002 REV.2) 적용 결과를 더했습니다. 초판 2026-09-14.
A3: 주식회사 퍼스트씨앤디 · 작성일 2026. 09. 17
A5: 시트 | B5: 내용
A6: 요약 | B6: 시트별 항목 수를 수식으로 집계
A7: 수집데이터_전력 | B7: 태양광·ESS·계통·부지 공통 설비에서 보통 받는 운전 데이터(텔레메트리)
A8: 수집데이터_수소 | B8: 수전해·압축저장·연료전지에서 보통 받는 운전 데이터 + 가평 도면으로 더한 부속 계통 39행(산소·폐열·수처리·감압·반입)
A9: 운영·비정형 데이터 | B9: 명판·정비이력·알람코드·점검사진·설정값 등 계측 외 데이터 + 반입·출하 전표 등 장부 데이터
A10: 설계수명·교체주기 | B10: 설비별 기대수명, 대표 열화율, 소모품·점검 주기
A11: 법정 점검 | B11: 국내 법정 정기검사·자체점검 주기
A12: 분석항목×주기 | B12: 월간·분기·연간 AI 분석으로 판정 가능한 항목과 리포트 문장 예시(가평 구성 탐지기 3종 포함)
A13: 정기 리포트 구성 | B13: 월간·분기·연간·수시 리포트의 표준 섹션
A14: AI 분석 방법 | B14: 현장 질문 → 입력 데이터 → 방법 → 결과 → 개선 코칭. 마지막 2행은 실제로 구현된 AI 설명 층
A15: 개선항목·기대효과 | B15: 노후 지연·손실 회수 등 개선 여지와 근거
A16: 축적기간별 로드맵 | B16: 데이터가 쌓이는 기간별로 가능해지는 분석
... A21: 범례 | B21: 우선순위 필수=핵심 판정에 반드시 필요 / 권장=정확도·오탐 방지 / 선택=있으면 좋음. 주기 ●=해당 주기 리포트에서 판정. 명판·값의 '미확인'은 추정으로 채우지 않고 남긴 값이며 회신 대기 목록입니다

Sheet 요약
A1: 수집 데이터 항목 수 (분야 × 우선순위)
A2: 다른 시트의 행을 COUNTIFS로 집계합니다. 원본 시트를 고치면 자동으로 바뀝니다. 아래 표에 분석 주기별 항목 수가 이어집니다.
A3: 주식회사 퍼스트씨앤디 · 작성일 2026. 09. 17
A5: 분야 | B5: 필수 | C5: 권장 | D5: 선택 | E5: 합계
A6: 태양광 | B6: =COUNTIFS(수집데이터_전력!$A:$A,"태양광",수집데이터_전력!$F:$F,"필수") -> 12 | C6: =COUNTIFS(수집데이터_전력!$A:$A,"태양광",수집데이터_전력!$F:$F,"권장") -> 7 | D6: =COUNTIFS(수집데이터_전력!$A:$A,"태양광",수집데이터_전력!$F:$F,"선택") -> 3 | E6: =SUM(B6:D6) -> 22
A7: ESS | B7: =COUNTIFS(수집데이터_전력!$A:$A,"ESS",수집데이터_전력!$F:$F,"필수") -> 16 | C7: =COUNTIFS(수집데이터_전력!$A:$A,"ESS",수집데이터_전력!$F:$F,"권장") -> 11 | D7: =COUNTIFS(수집데이터_전력!$A:$A,"ESS",수집데이터_전력!$F:$F,"선택") -> 1 | E7: =SUM(B7:D7) -> 28
A8: 연계·계통 | B8: =COUNTIFS(수집데이터_전력!$A:$A,"연계·계통",수집데이터_전력!$F:$F,"필수") -> 22 | C8: =COUNTIFS(수집데이터_전력!$A:$A,"연계·계통",수집데이터_전력!$F:$F,"권장") -> 8 | D8: =COUNTIFS(수집데이터_전력!$A:$A,"연계·계통",수집데이터_전력!$F:$F,"선택") -> 2 | E8: =SUM(B8:D8) -> 32
A9: 수전해(PEM) | B9: =COUNTIFS(수집데이터_수소!$A:$A,"수전해(PEM)",수집데이터_수소!$F:$F,"필수") -> 13 | C9: =COUNTIFS(수집데이터_수소!$A:$A,"수전해(PEM)",수집데이터_수소!$F:$F,"권장") -> 8 | D9: =COUNTIFS(수집데이터_수소!$A:$A,"수전해(PEM)",수집데이터_수소!$F:$F,"선택") -> 1 | E9: =SUM(B9:D9) -> 22
A10: 압축·저장·안전 | B10: =COUNTIFS(수집데이터_수소!$A:$A,"압축·저장·안전",수집데이터_수소!$F:$F,"필수") -> 17 | C10: =COUNTIFS(수집데이터_수소!$A:$A,"압축·저장·안전",수집데이터_수소!$F:$F,"권장") -> 5 | D10: =COUNTIFS(수집데이터_수소!$A:$A,"압축·저장·안전",수집데이터_수소!$F:$F,"선택") -> 2 | E10: =SUM(B10:D10) -> 24
A11: 연료전지(PEM) | B11: =COUNTIFS(수집데이터_수소!$A:$A,"연료전지(PEM)",수집데이터_수소!$F:$F,"필수") -> 23 | C11: =COUNTIFS(수집데이터_수소!$A:$A,"연료전지(PEM)",수집데이터_수소!$F:$F,"권장") -> 13 | D11: =COUNTIFS(수집데이터_수소!$A:$A,"연료전지(PEM)",수집데이터_수소!$F:$F,"선택") -> 4 | E11: =SUM(B11:D11) -> 40
A12: 공통·부지 | B12: =COUNTIFS(수집데이터_전력!$A:$A,"공통·부지",수집데이터_전력!$F:$F,"필수") -> 12 | C12: =COUNTIFS(수집데이터_전력!$A:$A,"공통·부지",수집데이터_전력!$F:$F,"권장") -> 9 | D12: =COUNTIFS(수집데이터_전력!$A:$A,"공통·부지",수집데이터_전력!$F:$F,"선택") -> 0 | E12: =SUM(B12:D12) -> 21
A13: 부산물 산소 | B13: =COUNTIFS(수집데이터_수소!$A:$A,"부산물 산소",수집데이터_수소!$F:$F,"필수") -> 5 | C13: =COUNTIFS(수집데이터_수소!$A:$A,"부산물 산소",수집데이터_수소!$F:$F,"권장") -> 1 | D13: =COUNTIFS(수집데이터_수소!$A:$A,"부산물 산소",수집데이터_수소!$F:$F,"선택") -> 0 | E13: =SUM(B13:D13) -> 6
A14: 폐열회수 | B14: =COUNTIFS(수집데이터_수소!$A:$A,"폐열회수",수집데이터_수소!$F:$F,"필수") -> 6 | C14: =COUNTIFS(수집데이터_수소!$A:$A,"폐열회수",수집데이터_수소!$F:$F,"권장") -> 4 | D14: =COUNTIFS(수집데이터_수소!$A:$A,"폐열회수",수집데이터_수소!$F:$F,"선택") -> 0 | E14: =SUM(B14:D14) -> 10
A15: 수처리 | B15: =COUNTIFS(수집데이터_수소!$A:$A,"수처리",수집데이터_수소!$F:$F,"필수") -> 9 | C15: =COUNTIFS(수집데이터_수소!$A:$A,"수처리",수집데이터_수소!$F:$F,"권장") -> 3 | D15: =COUNTIFS(수집데이터_수소!$A:$A,"수처리",수집데이터_수소!$F:$F,"선택") -> 0 | E15: =SUM(B15:D15) -> 12
A16: 감압·버퍼 | B16: =COUNTIFS(수집데이터_수소!$A:$A,"감압·버퍼",수집데이터_수소!$F:$F,"필수") -> 2 | C16: =COUNTIFS(수집데이터_수소!$A:$A,"감압·버퍼",수집데이터_수소!$F:$F,"권장") -> 1 | D16: =COUNTIFS(수집데이터_수소!$A:$A,"감압·버퍼",수집데이터_수소!$F:$F,"선택") -> 0 | E16: =SUM(B16:D16) -> 3
A17: 외부 반입 | B17: =COUNTIFS(수집데이터_수소!$A:$A,"외부 반입",수집데이터_수소!$F:$F,"필수") -> 7 | C17: =COUNTIFS(수집데이터_수소!$A:$A,"외부 반입",수집데이터_수소!$F:$F,"권장") -> 1 | D17: =COUNTIFS(수집데이터_수소!$A:$A,"외부 반입",수집데이터_수소!$F:$F,"선택") -> 0 | E17: =SUM(B17:D17) -> 8
A18: 합계 | B18: =SUM(B6:B17) -> 144 | C18: =SUM(C6:C17) -> 71 | D18: =SUM(D6:D17) -> 13 | E18: =SUM(E6:E17) -> 228
A20: 분석 주기 | B20: 항목 수
A21: 월간 | B21: =COUNTIF(분석항목×주기!E:E,"●") -> 39
A22: 분기 | B22: =COUNTIF(분석항목×주기!F:F,"●") -> 16
A23: 연간 | B23: =COUNTIF(분석항목×주기!G:G,"●") -> 23

Sheet 수집데이터_전력
A1: 태양광·ESS·계통·공통에서 보통 받는 데이터
A2: 인버터·BMS·계량기·기상센서 등에서 수집하는 운전 데이터. 우선순위 필수 항목부터 데이터 계약에 넣기를 권장합니다.
A3: 주식회사 퍼스트씨앤디 · 작성일 2026. 09. 17
A5: 분야 | B5: 구성품 | C5: 데이터 항목 | D5: 단위 | E5: 수집 주기 | F5: 우선순위 | G5: 이 데이터로 알 수 있는 것 | H5: 출처·장치·프로토콜
A6: 태양광 | B6: PV 스트링 | C6: 스트링별 전류 | D6: A | E6: 1~5분(가능하면 1분) | F6: 필수 | G6: 피어 비교로 스트링 개방·저성과·음영·국부 결함을 스트링 단위로 특정. 없으면 MPPT 채널 단위까지만 추론 가능. | H6: 스트링 인버터 입력 레지스터 또는 감시형 접속반 CT(SunSpec 403/404)
A7: 태양광 | B7: 인버터 DC 측 | C7: MPPT 채널별 전압·전류 | D7: V, A | E7: 1분 | F7: 필수 | G7: 기대 Vmp 대비 전압 비로 바이패스 다이오드 단락(1/3 모듈 계단)·PID 판정, 채널 간 kWh/kWp 비교로 MPPT 추종 불량 탐지. | H7: SunSpec 160, 제조사 Modbus
A8: 태양광 | B8: 인버터 DC 측 | C8: 절연저항(Riso) 기동 시 측정값 | D8: kΩ | E8: 기동 시 1회/일(가능하면 연속) | F8: 필수 | G8: 습도 보정 후 추세 하락으로 백시트 크랙·박판 유리 파손·케이블 손상·커넥터 침수를 선제 탐지. 화재·감전 위험 지표. | H8: SunSpec 122 Ris 또는 제조사 레지스터
A9: 태양광 | B9: 인버터 AC 측 | C9: 운전 상태·고장코드·경고 비트(원시 코드 + 타임스탬프) | D9: enum/bitfield | E9: 변화 시 이벤트 + 1분 폴링 | F9: 필수 | G9: 모드 분리(대기/MPPT/클리핑/출력제한/디레이팅/트립), 트립 원인 분류, 고장 빈도 추세. AI 고장 분류의 라벨 원천. | H9: SunSpec 103 St/Evt, 제조사 이벤트 로그
A10: 태양광 | B10: 인버터 AC 측 | C10: 출력제한 설정값·무효전력 모드·역률 설정(설정 스냅샷) | D10: %, mode, PF | E10: 변화 시 + 일 1회 스냅샷 | F10: 필수 | G10: 출력제어 손실과 고장 손실 분리, 설정 잔존·펌웨어 업데이트 후 기본값 복귀 검출, Volt-Var 운전에 따른 유효전력 영향 해석. | H10: SunSpec 123/126(Volt-Var)/127, 제조사 레지스터, 중개사업자·KPX 지령 이력
A11: 태양광 | B11: 인버터 AC 측 | C11: 방열판·IGBT·함체 온도 및 디레이팅 플래그 | D11: °C, bool | E11: 1~5분 | F11: 필수 | G11: 부하·외기 bin 대비 온도 상승으로 팬·필터·방열 열화와 IGBT 열화를 조기 탐지. 디레이팅 손실량 산출. | H11: SunSpec 103 TmpSnk/TmpCab/TmpTrns, 제조사 레지스터
A12: 태양광 | B12: 인버터 AC 측 | C12: AC 유효·무효전력, 상전압·상전류, 주파수, 누적 kWh | D12: kW, kvar, V, A, Hz, kWh | E12: 1분(kWh 5~15분) | F12: 필수 | G12: 기본 발전 성과, 효율(P_AC/P_DC), 상 불평형, 계통 전압 상승 트립 원인 분석. | H12: SunSpec 103, REMS 항목
A13: 태양광 | B13: 기상센서 | C13: 경사면 일사(POA)·모듈온도·외기온·풍속 | D13: W/m², °C, m/s | E13: IEC 61724-1 Class A: 3초 샘플/1분 기록(실무 최소 1분 평균) | F13: 필수 | G13: 기대발전량(물리 모델)과 온도보정 PR의 입력. 이 값의 정확도가 모든 손실 분해의 상한을 정한다. | H13: ISO 9060 일사계/기준셀, PT100, SunSpec 302/303
A14: 태양광 | B14: 기상센서 | C14: 위성·수치예보 일사/기온(외부 API) | D14: W/m², °C | E14: 실황 10~15분, 예보 1시간(익일 48시간) | F14: 필수 | G14: 현장 일사계 드리프트 교차검증, 센서 없는 소규모 사이트의 기대발전량, 발전량 예측(KPX 예측제도) 입력. | H14: 기상청 ASOS·동네예보/천리안 위성 일사, 상용 일사 API
A15: 태양광 | B15: 변압기·수배전 | C15: 변압기 온도, 보호계전기 동작 이벤트, VCB 상태 | D15: °C, event | E15: 5분 + 이벤트 | F15: 필수 | G15: 사이트 전체 정지 원인(수배전 트립 vs 계통 정전 vs 인버터) 분리, 변압기 과열 추세. | H15: 디지털 보호계전기(Modbus/DNP3/IEC 61850), 온도계전기 4-20mA
A16: 태양광 | B16: 계량 | C16: 한전 거래용 계량기 15분 송·수전 kWh | D16: kWh | E16: 15분 | F16: 필수 | G16: 수익 기준 발전량, 인버터 합계와 비교한 AC 측 손실·계측 오류, 야간 수전(무부하손) 추세. | H16: 한전 AMI(파워플래너 등), 사이트 전력량계
... A108: 공통·부지 | B108: ESS | C108: BMS 블랙박스·트립 직전 버퍼 제공 여부·이력 | D108: 파일·이벤트 | E108: 사고·트립 시 | F108: 권장 | G108: 사고 원인 분석, 보증 청구 증빙 | H108: BMS OEM 서비스 요청(계약 조항)

Sheet 수집데이터_수소
A1: 수전해·압축저장·연료전지·부속 계통에서 보통 받는 데이터
A2: PEM 전해조·수소 압축기·고압 저장·PEM 연료전지 기준. 안전 인터록 신호는 분석과 별도로 즉시 알람 대상입니다. 분야 ‘부산물 산소’~‘외부 반입’ 39행은 가평 2MW 청정수소발전 P&ID(FCND-GP-PID-002 REV.2)를 받아 더한 부속 계통 항목이며, 우선순위는 그 사이트의 매핑·신설 요청 구분입니다(필수=도면 태그가 있거나 없으면 판정 불가, 권장=정확도·오탐 방지).
A3: 주식회사 퍼스트씨앤디 · 작성일 2026. 09. 17
A5: 분야 | B5: 구성품 | C5: 데이터 항목 | D5: 단위 | E5: 수집 주기 | F5: 우선순위 | G5: 이 데이터로 알 수 있는 것 | H5: 출처·장치·프로토콜
A6: 수전해(PEM) | B6: 정류기 | C6: 무효전력·역률·전류 THD | D6: kvar / ratio / % | E6: 1 s 수집, 1 min 집계 | F6: 필수 | G6: 역률요금·보상설비 필요성, 다스택 전류 배분 최적화의 제약조건 | H6: 수전단 전력분석기(IEC 61000-4-30 Class A 권장)
A7: 수전해(PEM) | B7: 스택 | C7: 스택 전류·전압 | D7: A / V | E7: 1 s(이벤트 시 100 ms) | F7: 필수 | G7: 운전점, SEC, 계단응답 저항, 분극곡선 적합 | H7: 정류기/PLC
A8: 수전해(PEM) | B8: 셀 | C8: 셀(그룹) 전압 배열 | D8: mV | E8: 1 s 수집, 1 min mean/min/max 저장 | F8: 필수 | G8: 약한 셀 조기 발견, 단락·유로 막힘, 체결 불균일 | H8: CVM(CAN/Modbus)
A9: 수전해(PEM) | B9: 기액분리기 | C9: H2/O2 분리기 수위와 수위차 | D9: % / mm | E9: 1 s | F9: 필수 | G9: 균압 제어 품질, 액적 동반, 인터록 여유 | H9: 레벨전송기→PLC
A10: 수전해(PEM) | B10: AWE 전해액 루프 | C10: 스택별 전해액 유량·순환모드 | D10: m³/h / enum | E10: 1 s | F10: 필수 | G10: HTO 거동 해석, 유량 분배 불균일, 펌프·필터 상태 | H10: PLC
A11: 수전해(PEM) | B11: 냉각 | C11: 스택 전단(분리기측)·후단 온도, 냉각밸브 개도 | D11: °C / % | E11: 1 s | F11: 필수 | G11: 온도제어 성능(진동·편차), 열교환 UA, 효율 손실 원인 | H11: RTD→PLC
A12: 수전해(PEM) | B12: 가스 분석 | C12: HTO·OTH | D12: %vol | E12: 1 s | F12: 필수 | G12: 안전여유, 최소 안전부하, 막/격막 열화 | H12: 열전도식/상자성 분석기 4-20 mA
A13: 수전해(PEM) | B13: 정제 | C13: Deoxo 입·출구 온도, 제품 O2, 이슬점 | D13: °C / ppm / °C | E13: 10 s | F13: 필수 | G13: 촉매 활성, 분석기 교차검증, 제품 품질(ISO 14687) | H13: 정제기 PLC·미량분석기
A14: 수전해(PEM) | B14: 순수 제조 | C14: RO·EDI·루프 이온교환기 전후 전도도 | D14: µS/cm | E14: 10 s | F14: 필수 | G14: 오염 선행지표, 수지 교체 시점 | H14: 전도도계(25 °C 보상)
A15: 수전해(PEM) | B15: 시스템 | C15: 운전 상태·전환 사유·트립 코드 | D15: enum | E15: 이벤트 + 1 s | F15: 필수 | G15: 모든 지표의 조건 필터, 운전 패턴 코칭 근거 | H15: PLC 알람/이벤트 로그
A16: 수전해(PEM) | B16: 시스템 | C16: 수소 유량(건조기 전·후)·출구 압력 | D16: kg/h / bar(g) | E16: 1 s | F16: 필수 | G16: 패러데이 효율, 재생 손실, 누설 | H16: 코리올리/열식 유량계
... A130: 외부 반입 | B130: 외부 수소 반입 설비 | C130: 누적 수소 방출량 | D130: kg | E130: 60초 | F130: 권장 | G130: 누적 방출량. 지금 원장의 vented_est는 퍼지 횟수 추정뿐이라 하역 벤트가 통째로 잔차에 섞인다. | H130: P&ID FCND-GP-PID-002 REV.2 · 계장 태그 FT-502 · 조사 research-supply

Sheet 운영·비정형 데이터
A1: 계측 외에 함께 받아야 하는 데이터
A2: 명판·설계정보, 정비이력(=AI 학습 라벨), 알람코드, 점검 사진, 설정값 변경, 기상·시장가격, 반입·출하 전표 등.
A3: 주식회사 퍼스트씨앤디 · 작성일 2026. 09. 17
A5: 분야 | B5: 데이터 | C5: 예시 | D5: 왜 필요한가
A6: 태양광 | B6: 설계·명판 정보(디지털 트윈 기초자료) | C6: 모듈 데이터시트(Pmax, Voc/Isc/Vmp/Imp, 온도계수 γ·β, 양면율, NMOT, 셀 기술 PERC/TOPCon/HJT, 유리 두께), 인버터 사양(MPPT 전압창, 효율 곡선, 디레이팅 곡선), 스트링 맵(인버터-MPPT-스트링-모듈 위치), 경사·방위·GCR, 단선결선도, 배치도(GIS 좌표/행·열 번호), 케이블 길이·단면적, 준공일 | D6: 기대발전량 모델(pvlib 등)과 피어 그룹 정의에 필요. 드론 IR 결함 좌표를 스트링·인버터 채널에 매핑하는 기준. 셀 기술별로 우선 감시할 열화 모드(PERC는 LeTID·PID, TOPCon/HJT는 UVID, 박판 G/G는 유리 파손)가 달라진다.
A7: 태양광 | B7: 준공·정기 시험 성적(베이스라인) | C7: IEC 62446-1 준공 시험(스트링 Voc/Isc, 절연저항, IV 커브), 모듈 출하 플래시 데이터(모듈별 Pmax), 출하 EL 이미지, 한전 연계 시험·KS C 8564/8565 시험성적서, 전기안전공사 사용전·정기검사 결과 | D7: 열화율과 IV 변화의 기준점. 출하 EL은 보증 청구 시 제조 결함과 현장 손상을 가르는 증거(IEA PVPS T13-10).
A8: 태양광 | B8: 드론 열화상(IR) 점검 데이터 | C8: 방사측정(radiometric) 원본 IR 영상, 가시광 정사영상, 촬영 시 POA·풍속·외기온, 결함 목록(핫스팟·서브스트링·모듈 전체·스트링 개방·다이오드·오염 패턴), 좌표, 결함별 ΔT, 권장 조치 | D8: 원격 데이터로 특정할 수 없는 모듈 단위 결함 위치를 확정. IR 촬영은 POA>600 W/m², 구름 없음, 약풍, 안정 조건에서 수행하고 모듈 열 안정화에 5~15분이 걸린다(IEA PVPS T13-10). 결함 비율이 모듈의 10%를 넘으면 품질·시공 원인 조사가 권고된다. AI 이미지 모델의 학습·검증 라벨로도 쓴다.
A9: 태양광 | B9: EL(전계발광)·UV 형광 이미지 | C9: 야간 역전류 인가 EL 이미지(모듈/스트링 단위), 주간 EL(PL) 이미지, 셀별 결함 라벨(크랙 A/B/C, 비활성 영역, 핑거 단선, PID 체커보드 패턴) | D9: 크랙·PID·납땜 불량 등 IR로는 약하게 보이는 결함을 셀 해상도로 확인. 수작업 야간 EL은 하룻밤 약 0.2 MWp 수준이라(IEA PVPS T13-10) IR·원격 분석으로 대상을 먼저 좁혀야 경제적이다.
A10: 태양광 | B10: 정비 이력·작업지시(텍스트) | C10: 작업지시서, 현장 조치 메모, 교체 부품(퓨즈·커넥터·팬·IGBT 모듈·인버터 전체), 출동 시각·완료 시각(MTTR), 세척 일자·방식·비용, 제초·수목 제거 기록, 보증 청구·RMA 결과 | D10: AI 고장 분류의 정답 라벨과 조치 효과 검증(세척 후 SR 회복, 교체 후 전류비 회복). Sandia·NREL은 5.5만 건의 정비기록을 ML로 분류해 인버터 빈발 고장 하위계통을 도출했다. 비정형 텍스트는 LLM/NLP로 구조화한다.
A11: 태양광 | B11: 알람·이벤트 로그 원본과 코드 사전 | C11: 제조사별 고장코드 표(코드→의미→권장조치), 경보 발생/해제 시각, 수동 리셋 기록, 펌웨어 버전 변경 이력 | D11: 다제조사 코드를 공통 고장 분류 체계로 매핑하는 기준. 코드 빈도 추세가 예지 모델의 핵심 특징량.
A12: 태양광 | B12: 운영 설정값 이력 | C12: 계통 보호 설정표(전압·주파수 단계/시간), LVRT/HVRT/LFRT 적용 여부, 역률·Volt-Var 설정, 출력제한 %, 램프율, 전역 MPPT 스윕 설정, 디레이팅 설정 | D12: 설정 오류·잔존에 따른 손실을 고장과 구분. 2025년 500kW 이상 HVRT·LFRT 설정 개선 같은 규제 이행 확인.
A13: 태양광 | B13: 출력제어·시장 데이터 | C13: KPX·중개사업자 출력제어 지령(시각·%), SMP·REC 가격, 발전량 예측제도 제출값·정산 결과, 계약 형태(RPS/PPA/입찰) | D13: 손실을 원(₩) 단위로 환산해 조치 우선순위(세척·수리·교체)를 경제성으로 정렬. 출력제어 구간 제외.
A14: 태양광 | B14: 기상·환경 외부 데이터 | C14: 기상청 ASOS 강수·적설·황사 특보, 미세먼지(PM10/PM2.5) 농도, 천리안 위성 일사, 주변 식생·신축 구조물 위성/항공 사진 | D14: 오염 누적·강우 세정 모델, 적설 기간 분석 제외, 신규 음영 원인 확인.
A15: 태양광 | B15: 자산·보증·보험 정보 | C15: 모듈·인버터 보증 조건(출력 보증 곡선, 인버터 10년 보증 연장 여부), 보험 약관, 예비품 재고, 인버터 단종·부품 공급 상태 | D15: 열화율이 보증 곡선을 넘어서는지 판단, 인버터 수리 vs 교체 의사결정, 예비품 최적화.
A16: ESS | B16: 셀·모듈 사양서와 OCV-SOC 곡선 | C16: 셀 화학(LFP/NMC)·정격용량·공칭전압, 충/방전 분기 OCV-SOC 표(온도별), 허용 전압·온도·C-rate, DCIR 초기값, 사이클 수명 조건, UL 9540A 시험 결과 | D16: 칼만필터 SOC·ICA·보호 한계 근접도 계산의 물리 기준. LFP 히스테리시스를 모르면 SOC 재추정이 틀린다
... A141: 장부·전표 | B141: 도면 리비전과 명판 회신 | C141: P&ID 리비전 번호, 압력 기준(게이지/절대), Nm³ 기준조건(0/15/20 °C), 감압 단수·조정기 등급, 열교환기 벽 구조, 트레일러 형식 | D141: 숫자가 아니라 해석의 기준이다. 미확인이면 질량 환산과 임계가 전부 가정 위에 선다(수소 재고 3.3%, Nm³ 환산 약 7% 차이)

Sheet 설계수명·교체주기
A1: 설비별 설계수명·열화율·교체주기
A2: [n]은 '출처' 시트 번호. '추정'은 원문에서 확인하지 못한 값이며 제조사 매뉴얼로 확정해야 합니다.
A3: 주식회사 퍼스트씨앤디 · 작성일 2026. 09. 17
A5: 분야 | B5: 설비 | C5: 설계수명·기준 | D5: 대표 열화·신뢰성 | E5: 교체·점검 주기 | F5: 출처
A6: 태양광 | B6: PV 모듈 | C6: 사업 수명 30년 가정(ATB) [16]. 보증 예: 30년 선형, 첫해 ≤1%, 이후 −0.4%/년. 30년차 약 87.4%는 계산 [15] | D6: 문헌 약 2,000건 중앙값 0.5%/년 [1]. 결정질 Si 중앙값 0.5~0.6%/년, 평균 0.8~0.9%/년 [2]. 미국 시스템 성능저하율 중앙값 −0.75%/년, 오염 제외 시 약 −0.5%/년, 온대 −0.5 ~ 고온 −0.88%/년 [3]. ATB 가정 0.7%/년 [16] | E6: 무결성 점검 반기(최소 요건), 열화상 반기(권고), 세척은 현장 조건(자동세척이 없으면 반기) [9]. 이상 모듈 출력시험 5년 주기 예시 [8] | F6: [1][2][3][9][15][16]
A7: 태양광 | B7: 스트링·접속반 | C7: 플랜트 수명 동안 퓨즈·서지보호기 등 부품 교체(추정) | D7: 소형 설비는 알람 누락이 잦음(추정) | E7: 접속반 개방 점검(퓨즈·체결·침수·부식·IR) 연 1회 [8]. 퓨즈 상태 연 1회(표본), 케이블 절연저항 연 1회 [9]. 유지보수 요건은 IEC 62446-2 [24] | F7: [8][9][24]
A8: 태양광 | B8: 인버터(PCS) | C8: 수명은 통상 15년으로 언급 [18]. 보증 10년 표준, 20년 연장 증가 [8] | D8: 평균고장간격(MTBF) 약 11~12년이라 플랜트 수명 중간쯤 교체 예상 [12]. MTBF 1~16년 [19]. 스위스 주거용은 15년차에 34.3%가 첫 고장 [18]. 운영사 사례에서 에너지 손실의 36%가 인버터 [19] | E8: 필터 청소 반기·교체 2년, 퓨즈·서지보호기 반기, 환기 기능시험 반기, 열화상 연 1회, 배터리·팬 교체는 제조사 권고(예시 3년·5년) [9]. 전해 커패시터 수명은 온도가 10°C 내려갈 때마다 2배 [20] | F8: [8][9][12][18][19][20]
A9: 태양광 | B9: 변압기·계통연계 | C9: IEEE C57.91 기준, 최고점 110°C 연속 운전 시 정상 절연수명 20.55년(보수적 기준) [21] | D9: 과부하·고온 시 수명 소모 가속 [21] | E9: 유면·최고온도 연 1회, 절연유 분석 연 1회(모범사례), 보호 파라미터·기능점검 3~5년(계통코드), 전력량계 교정 3년(현지 규정) [9]. 전기사업용 신재생 변전소 정기검사 4년 이내 [31] | F9: [9][21][31]
A10: 태양광 | B10: 기상센서(일사계·모듈온도) | C10: 교정 주기로 관리 | D10: 센서가 오염되거나 교정이 틀어지면 위성 일사보다 부정확 [8] | E10: IEC 61724-1 Class A: 일사계 교정 2년 1회, 세척 주 1회, 전면 센서 점검 주 1회, 전체 시스템 점검 연 1회, 모듈온도 스테이션당 3개 [13]. 일사계 재교정 2년 [9]. 일사계·데이터로거 상태는 매일 확인 권장 [8] | F10: [8][9][13]
A11: ESS | B11: 셀·모듈·랙 | C11: 캘린더 수명 LFP 16년, NMC 13년 [25]. 보증 예: 10~15년 또는 80% DOD 10,000사이클 [25]. ATB 가정: 15년(보강비 포함), 하루 1사이클, RTE 85% [17] | D11: LFP가 정격의 60%(PNNL 수명말 정의)에 이르는 사이클(DOD): 4,800(100%), 6,000(80%), 8,000(60%), 32,000(30%). 완전사이클 환산은 60%까지 4,800으로 같고, 30%에서 9,600 [25]. 캘린더 열화는 온도에 강하게, SOC에 약하게 의존 [28]. 제조사 사양 안에서도 조건에 따라 80% 도달 시간이 수천 시간 차이 [29] | E11: 교체 기준 예: 초기 용량의 70% [8]. 보강·교체 시점은 DOD 기준 사이클 수명과 캘린더 수명 중 짧은 쪽 [25]. 용량시험은 조건 기반 [8] | F11: [8][17][25][28][29]
A12: ESS | B12: BMS·제어 | C12: 추정(플랜트 수명 동안 펌웨어 관리) | D12: 원인이 분류된 ESS 사고 26건 중 셀 직접 원인은 3건(11%) [27]. 국내 화재 조사에서 절연성능 급락이 먼저 나타남 [30] | E12: 충전율 제한 옥내 80%·옥외 90%, 운영데이터 블랙박스 권고 [30] | F12: [27][30]
A13: ESS | B13: ESS PCS | C13: 전력설비 대정비 10년마다(전력설비 비용의 30%) [25] | D13: 인버터 계열 부품 열화는 A-1 준용(추정) | E13: 연간 소정비(점검·필터 교체·정렬) [25] | F13: [25]
A14: ESS | B14: 공조(HVAC)·환기 | C14: 추정 | D14: 공조 성능 저하가 셀 온도 상승으로 이어짐(추정) | E14: 필터 교체·기능점검 연 1회(제조사 권고) [9]. 환기·필터는 필요 시 교체 [8] | F14: [8][9]
A15: ESS | B15: 법정 | C15: — | D15: — | E15: ESS 전기설비 정기검사: 다중이용 건물 안 설치 또는 1,000 kWh 이상은 1년 이내, 그 외 2년 이내 [31] | F15: [31]
A16: 수전해(PEM) | B16: 스택 | C16: DOE 2022 현황 40,000 h(4.8 mV/kh = 0.25%/kh), 2026 목표 80,000 h(2.3 mV/kh). 수명말 = 초기 대비 전압 10% 상승 [32]. IRENA PEM 50,000~80,000 h(2020) → 100,000~120,000 h(2050 목표) [33]. EPRI 60,000~80,000 h(연속운전 7~10년) [34]. PNNL 가정 60,000 h마다 교체 [25] | D16: EPRI: PEM 기저부하 1~1.5%/년, 알칼라인 약 1%/년 [34]. Clean Hydrogen JU PEM: 0.19(2020) → 0.15(2024) → 0.12%/1,000 h(2030) [35]. 열화 평가에는 정상·동적·온오프 운전을 포함해야 함 [32] | E16: 스택 교체비는 시스템 CAPEX의 35~45% [34]. 초기 활성화 구간은 최소 1,000 h 이후부터 성능 기준점을 잡음 [38] | F16: [25][32][33][34][35][38]
... A21: 수전해(PEM) | B21: 자동차단밸브 | C21: 개폐 내구 250,000회 또는 제조자 제시값 [40] | D21: — | E21: 개폐횟수 자동 기록, 제조자 값의 85% 초과 시 경보, 90% 초과 시 기동금지 [40] | F21: [40]
A22: 압축·저장·안전 | B22: 다이어프램 압축기 | C22: 고객 보고로 오일 교환 외 무교체 10,000~40,000 h, 정비 4~8 h(제조사 자료) [47]. 다이어프램 파단이 가장 흔한 고장 [48]. 충전소 정비 4,663건 중 69%가 비계획이고, 디스펜서·압축기·칠러가 78% [46] | E22: 다이어프램·밸브·링 교체 주기는 제조사 매뉴얼(공개 대표값 미확인, 추정). 압축기 최종단 안전밸브 조정 연 1회 이상, 그 밖 안전밸브 2년 1회 이상 [45] | F22: [45][46][47][48]
A23: 압축·저장·안전 | B23: 고압 저장용기 | C23: 복합재료용기는 제조검사 후 15년에 폐기 [44] | E23: 이음매 없는 용기·복합재료용기 재검사: 500 L 이상 5년마다, 500 L 미만은 10년 이하 5년·초과 3년마다. 저장탱크 5년, 압력용기 4년마다 [44]. 저장능력 100 m³ 이상 저장설비 침하 측정 연 1회 이상 [41] | F23: [41][44]
A24: 압축·저장·안전 | B24: 밸브·압력계 | C24: — | E24: 충전용 주관 압력계 매월, 그 밖 압력계 연 1회 기능검사 [45]. 저장탱크 부착 안전밸브·긴급차단장치는 탱크 재검사 때마다 [44] | F24: [44][45]
A25: 압축·저장·안전 | B25: 가스검지기 | C25: DOE 목표 센서 수명 10년. 교정 부담이 도입 장벽이며 5년 이상 무교정이 이상적 [49] | E25: 운전 중 하루 1회 이상 가스누출 경보장치 상태 점검 [41]. 교정 주기는 제조사 기준(통상 3~12개월, 추정) | F25: [41][49]
A26: 연료전지(PEM) | B26: 스택 | C26: DOE 정치형 CHP 1~25 kW: 60,000 h(순출력 20% 초과 저하까지), 100 kW~3 MW: 80,000 h(10% 초과 저하까지), 가용률 99% [50]. IEA AFC: PEMFC 60,000~80,000 h, 1%/년, 마이크로 CHP 스택 내구 40,000 → 80,000 h [51]. PNNL 가정 40,000 h마다 교체 [25]. EPA: 스택 교체 5~10년 [52] | D26: DOE 1~25 kW 사이클 운전 열화 목표 0.3%/1,000 h(2020) [50]. Clean Hydrogen JU 소형(5 kWe 미만) 정치형: 0.4%/1,000 h(2020) → 0.2(2030), 가용률 97~98% [35] | E26: 수명 저하 기여: 차량용 연구 기준 부하변동 약 57%·기동정지 약 33%(Pei 2008, 2차 인용, 정치형은 재산정) [53]. 개방회로전압(OCV) 유지·유휴는 막 열화를 가속 [56] | F26: [25][35][50][51][52][53][56]
A27: 연료전지(PEM) | B27: 공기 블로워·필터·가습기 | C27: 추정 | D27: 추정 | E27: 공기·연료 필터, 수처리 베드 등은 2,000~4,000 h 간격 교체 예상(연료전지 CHP 일반) [52] | F27: [52]
A28: 연료전지(PEM) | B28: 수소 재순환·퍼지·냉각(DI) | C28: 추정 | D28: 추정 | E28: 냉각수 전도도 기반 DI 필터 교체(추정). 원격감시·예지보전 포함 정비가 초기 상용기 관행 [52] | F28: [52]
A29: 연료전지(PEM) | B29: 연료전지 인버터 | C29: PV 인버터 신뢰성 준용(추정) [12][18] | D29: — | E29: A-1 준용 | F29: [12][18]

Sheet 법정 점검
A1: 국내 법정 점검·검사 주기
A2: 인허가 유형(고압가스 제조·저장·사용, 수소법)은 압력·저장능력·사업형태에 따라 달라지므로 한국가스안전공사 기술검토로 확정해야 합니다.
A3: 주식회사 퍼스트씨앤디 · 작성일 2026. 09. 17
A5: 대상 | B5: 주기 | C5: 비고 | D5: 출처
A6: 태양광·전기설비 계통(전기사업용) | B6: 4년 이내 | C6: 농지·임야·염전·공유수면에 설치한 태양광 부지·구조물은 2년 이내 | D6: [31]
A7: 연료전지·전기설비 계통 | B7: 4년 이내 | C7: 발전설비 검사는 가동정지 기간에 실시 | D7: [31]
A8: 전기저장장치(ESS) | B8: 1년 이내(1,000 kWh 이상 또는 다중이용 건물) / 2년 이내(그 외) | C8: — | D8: [31]
A9: 신재생 발전사업용 송전선로·변전소 | B9: 4년 이내 | C9: — | D9: [31]
A10: 수소연료사용시설(연료전지 설치·사용) | B10: 매 1년 전후 30일(다중이용시설 6개월) | C10: 수소법 시행령 제50조 | D10: [42]
A11: 수소연료사용시설 자체점검 | B11: 일일점검 1일 1회, 물분무장치 월 1회 | C11: 점검기록을 검토해 열화 경향을 파악하고 다음 보수계획·설비개선에 활용 | D11: [41]
A12: 가연성가스(수소) 제조·저장자(특정제조 외) | B12: 매 1년 전후 15일 | C12: 특정제조자는 4년 | D12: [43]
A13: 안전밸브·압력계 | B13: 최종단 1년 / 기타 2년, 압력계 월·연 | C13: A-4 참조 | D13: [45]
A14: 용기·특정설비 재검사 | B14: 3~5년, 압력용기 4년 | C14: 복합재료용기 15년 폐기 | D14: [44]

Sheet 분석항목×주기
A1: 월간·분기·연간 AI 분석으로 판정 가능한 항목
A2: ●=해당 주기 리포트에서 판정. 월은 이상·손실, 분기는 추세(잠정), 연간·YoY는 열화율·수명(확정). 최소 데이터 기간 미달이면 리포트에 '판정 보류'로 표기합니다. 분야 ‘감압·버퍼’·‘폐열회수’·‘부산물 산소’ 3행은 가평 P&ID를 받아 실제로 만든 탐지기이며, 리포트 문장은 구현된 탐지기의 출력 형식입니다.
A3: 주식회사 퍼스트씨앤디 · 작성일 2026. 09. 17
A5: 분야 | B5: 설비 | C5: 분석 항목 | D5: 무엇을 보나(데이터) | E5: 월 | F5: 분기 | G5: 연 | H5: 주기 상세 | I5: 최소 데이터 기간·해상도 | J5: 리포트 문장 예시 | K5: 출처
A6: 태양광 | B6: 플랜트 | C6: 발전량 대 기대치(EPI) | D6: 거래계량 kWh, 경사면 일사, 모듈온도, 위성 일사, 설비 모델 | E6: ● | G6: ● | H6: 월(연간 누적) | I6: 1개월, 15분 이하 | J6: "8월 발전량은 기상보정 기대치의 96.1%(−3.9%p). 이 중 출력제어 2.1%p, INV-03 트립 1.2%p." | K6: [9][10][11]
A7: 태양광 | B7: 플랜트 | C7: PR·온도보정 PR | D7: 발전량, 경사면 일사, 셀온도 | E7: ● | G7: ● | H7: 월(온도보정 PR은 2주~1개월), 연간 PR은 연 | I7: 1개월, 15분 이하 | J7: "온도보정 PR 0.842로 전년 동월 대비 −1.3%p. 동일 일사 구간 비교상 오염 영향 추정." | K7: [8][10]
A8: 태양광 | B8: 플랜트·인버터 | C8: 가용률(시간·에너지, 계약) | D8: 인버터 출력 0 구간, 계량-인버터 합 비교, 외부요인 제외 | E8: ● | G8: ● | H8: 월 집계, 연 계약평가 | I8: 첫 6개월은 초기 저가용률 구간으로 분리 | J8: "에너지 가용률 99.2%(외부요인 제외). INV-07이 1.4%p 기여, 1% 기준 초과로 중간보고 대상." | K8: [3][8][10][11]
A9: 태양광 | B9: 인버터 | C9: 트립·알람 통계, 고장간격 | D9: 이벤트 로그, 코드별 건수·지속시간·손실 | E9: ● | F9: ● | G9: ● | H9: 월(건수·손실), 분기(반복 패턴), 연(고장간격·교체 적립금) | I9: 이벤트 원자료 + 1분 출력 | J9: "3분기 INV-02 계통과전압 트립 14회(전분기 3회). 모두 11~13시, 연계점 전압 상승과 동시 발생." | K9: [8][11][19]
A10: 태양광 | B10: 인버터 | C10: 효율·방열판-외기 온도차·팬·필터 | D10: DC/AC 전력, 방열판 온도, 외기, 부하율 구간 | F10: ● | G10: ● | H10: 분기(계절 보정), 연 | I10: 동일 부하·외기 구간 3개월, 1~15분 | J10: "동일 부하·외기 구간에서 방열판 온도차가 +6°C. 필터 막힘 의심, 커패시터 수명 영향 있어 청소 권고." | K10: [9][20]
A11: 태양광 | B11: 인버터 | C11: 클리핑 손실 | D11: 출력 상한 체류시간, DC 가용전력 추정 | E11: ● | G11: ● | H11: 월(손실), 연(설계 검토) | I11: 1분 이하 권장(15분은 과소평가 가능, 추정) | J11: "5월 클리핑 추정 손실 1.8 MWh(0.4%)." | K11: [14] 추정
A12: 태양광 | B12: 모듈·어레이 | C12: 오염 손실·세척 판단 | D12: 일간 성능지수, 강수량, 미세먼지·황사 | E12: ● | F12: ● | G12: ● | H12: 월(건조구간 추세·세척 알림), 분기~연(세척 최적화) | I12: 14일 이상 무세척 구간, 일 집계, 다년 권장 | J12: "4월 황사 이후 오염률 −0.12%/일, 누적 손실 2.6% 추정. 세척비 대비 회수기간 9일로 세척 권고." | K12: [5][6][8][22]
A13: 태양광 | B13: 스트링·접속반 | C13: 스트링 전류 불균형(개방·다이오드·PID 초기) | D13: 동일 MPPT 내 스트링 전류 비, 모듈온도 보정 전압 | E13: ● | F13: ● | H13: 월(동종 비교), 반복 시 분기 | I13: 스트링·MPPT 1~15분, 청천일 수일 | J13: "CB-05 스트링 12의 전류가 동종 중앙값의 67%로 3주 지속. 개방·커넥터 점검 요망." | K13: [9] 방법은 추정
A14: 태양광 | B14: 모듈·시스템 | C14: 열화율(성능저하율·YoY) | D14: 일 집계 정규화 발전량(오염·가용률 보정) | G14: ● | H14: 연 | I14: 24개월 이상(신뢰 3~5년) | J14: "2년차 YoY 열화율 −0.62%/년(68% 신뢰구간 −0.41~−0.83). 보증 선형 −0.4%/년 초과 여부는 1년 추가 관측 필요." | K14: [3][4][5][15]
A15: 태양광 | B15: 어레이 | C15: 음영(수목 성장 등) | D15: 태양위치별 잔차 히트맵 | F15: ● | G15: ● | H15: 분기~연 | I15: 1년(태양 궤적 1주기) | J15: "12~1월 15시대 잔차가 전년 대비 확대. 서측 수목 성장 추정." | K15: [8] 추정
A16: 태양광 | B16: 계통 | C16: 출력제어 손실 분리 | D16: 출력제어 지시 기록, 제약 구간 발전량 | E16: ● | H16: 월 | I16: 이벤트 단위 | J16: "출력제어 4회로 추정 손실 3.1 MWh. 설비 손실에서 제외." | K16: [23]
A17: 태양광 | B17: 기상센서 | C17: 일사계 드리프트 | D17: 현장 일사 대 위성·인접 발전소 비율 | E17: ● | H17: 월 | I17: 청천일 다수 | J17: "POA/위성 비율이 3개월간 −4% 하향. 세척·재교정 필요(교정 만료 D−45)." | K17: [8][9][13]
A18: 태양광 | B18: 변압기 | C18: 유온·부하율, 절연유 분석 | D18: 유온·권선온도, 부하, 외기 / 절연유 분석 결과 | E18: ● | G18: ● | H18: 월(온도 추세), 연(절연유 분석) | I18: 계절 1주기 | J18: "동일 부하·외기에서 유온 +4°C. 냉각팬 점검. 연간 절연유 분석 결과 반영." | K18: [9][21]
A19: ESS | B19: 시스템 | C19: RTE(AC 기준, 보조전력 포함·제외) | D19: 충전·방전 kWh, 시작·종료 SOC | E19: ● | H19: 월 | I19: 완전 충방전 1회 이상 + 시작·종료 SOC [26], 1~15분 | J19: "월평균 RTE 86.1%(정격 88%). 공조 보조전력 증가가 1.2%p 기여." | K19: [17][26]
A20: ESS | B20: 랙·뱅크 | C20: 실증 용량·용량비 | D20: 동일 전류·온도·SOC 기준점 세션의 방전량 | F20: ● | G20: ● | H20: 분기(추세), 연(보증 대비) | I20: 조건 맞는 세션 다수, 1~10초 권장(추정) | J20: "동일 조건 세션 기준 용량 94.8%(연초 97.1%). 연환산 −3.1%p로 보증곡선 이내." | K20: [25][26]
A21: ESS | B21: 랙·뱅크 | C21: 수명(SOH)·보강 시점 예측·급락점 | D21: 용량 추세, 누적 완전사이클, 온도 이력 | F21: ● | G21: ● | H21: 분기(추세), 연(보강·교체 계획) | I21: 6~12개월, 급락점 탐지는 다년 | J21: "현 추세면 정격 80% 도달은 2034년 추정. 보강 예산 반영 권고." | K21: [25][29]
A22: ESS | B22: 셀·모듈 | C22: 셀 전압 편차·최저셀 | D22: 충전 종료·휴지 시 최대·최소 셀 전압, 위치 | E22: ● | F22: ● | H22: 월(이상), 분기(추세) | I22: 동일 조건 스냅샷 | J22: "Rack-3 Module-11 편차가 휴지 조건에서 2개월 연속 증가. 균형 불량·미세단락 의심." | K22: [8]; 판정 임계는 추정
A23: ESS | B23: 셀·공조 | C23: 온도 이력(최고·편차·고온 체류) | D23: 셀 최고·최저 온도, 실내온도, 공조 상태 | E23: ● | H23: 월 | I23: 1분 이하 | J23: "셀 32°C 초과 체류 41 h(전년 동월 12 h). 공조 COP 저하 동반." | K23: [8][28]
A24: ESS | B24: 운전 | C24: SOC 운전창 준수 | D24: SOC 분포, 상한 체류시간 | E24: ● | H24: 월 | I24: 1분 | J24: "옥외 설비 SOC 90% 한도 초과 0회. 상한 부근 체류 38 h." | K24: [30]
A25: ESS | B25: 운전 | C25: 사이클·DOD 분포 | D25: 레인플로 사이클 수, 완전사이클 누적 | E25: ● | G25: ● | H25: 월 집계, 연(보증 대비) | I25: 1분 | J25: "누적 1,012 완전사이클(보증 대비 10%). 평균 DOD 72%." | K25: [8][25]
A26: ESS | B26: 안전 | C26: 절연저항·BMS 보호동작·경보 | D26: 절연감시 로그, 경보 코드 | E26: ● | G26: ● | H26: 월(초기 2년은 강화) | I26: 이벤트 원자료 | J26: "DC 절연저항이 우천 후 회복되지 않음. 화재 전조 패턴 목록 대조." | K26: [27][30]
A27: ESS | B27: PCS | C27: 효율·트립 | D27: DC/AC 전력, 트립 로그 | E27: ● | F27: ● | H27: 월(트립), 분기(효율) | I27: 부하 구간별 | J27: "PCS-2 부분부하 효율 −0.8%p. 팬·필터 점검." | K27: [25] 추정
A28: ESS | B28: 공조 | C28: 소비전력·가동률·필터 | D28: 공조 kWh, 외기, 발열 | F28: ● | G28: ● | H28: 분기(계절 비교), 연 | I28: 계절 1주기 | J28: "동일 외기 구간 공조 전력 +15%. 필터 교체(연 1회) 조기 시행 권고." | K28: [9][25]
A29: 수전해(PEM) | B29: 시스템·스택 | C29: 비소비전력(kWh/kg, 스택·시스템 분리) | D29: 직류·교류 전력, 수소 유량, 부하 구간 | E29: ● | G29: ● | H29: 월(부하 구간별), 연(추세) | I29: 1개월, 1분 | J29: "30~60% 부하 구간 시스템 54.8 kWh/kg(기준 53.9). 15% 미만 저부하 운전이 18%로 효율 저하 기여." | K29: [32][33][40]
A30: 수전해(PEM) | B30: 스택 | C30: 기준조건 셀 평균전압 추세(µV/h) | D30: 전류밀도·온도·압력 구간별 셀전압 중앙값 | F30: ● | G30: ● | H30: 분기(추세 감시), 반기~연(열화율 확정) | I30: 초기 1,000 h 이후 1,000 h 이상 운전 | J30: "누적 3,100 h 기준 열화율 3.9 µV/h(DOE 2022 현황 4.8 이하). 확정은 누적 5,000 h 이후." | K30: [32][37][38]
A31: 수전해(PEM) | B31: 스택 | C31: 셀 간 편차·약한 셀 | D31: 셀전압 감시장치(CVM) 셀·그룹 전압 z-score | E31: ● | H31: 월 | I31: 동일 조건 스냅샷 | J31: "셀그룹 G17이 3개월 연속 +3σ. 막·다공성 수송층 국부 열화 의심." | K31: [37] 방법은 추정
A32: 수전해(PEM) | B32: 운전 | C32: 운전시간·기동정지·OCV 대기시간·램프 | D32: 운전상태 이벤트, 무전류 대기시간 | E32: ● | H32: 월 | I32: 이벤트 원자료 | J32: "기동정지 62회(전월 41). 무보호 OCV 대기 118 h. 보호전류 대기 운전 검토." | K32: [34][36]
A33: 수전해(PEM) | B33: 시스템 | C33: 가용률(스택·시스템) | D33: 운전 요구시간 대비 운전시간 | E33: ● | G33: ● | H33: 월, 연 | I33: — | J33: "요구 312 h 중 298 h 운전(가용률 95.5%). 순수 설비 경보 정지 14 h." | K33: [37]
A34: 수전해(PEM) | B34: 정제 | C34: 순도(수소 중 산소, 이슬점), 산소 중 수소 | D34: 분석기 값, 탈산소기 온도상승 | E34: ● | H34: 월(추세), 일(경보) | I34: 분석기 원자료 | J34: "이슬점 3개월 상승 추세. 건조기 재생 성능 점검." | K34: [39][40]
A35: 수전해(PEM) | B35: 순수설비 | C35: 전도도·수지 처리량 | D35: 급수·순환수 전도도, 수지 교체 간 처리량 | E35: ● | H35: 월 | I35: 교체 이벤트 포함 | J35: "수지 교체 간 처리량 −30%. 원수 수질 변화 또는 루프 금속 용출 의심." | K35: [33][34]
A36: 수전해(PEM) | B36: 정류기 | C36: 효율·온도 | D36: 교류/직류 전력비, 방열 온도 | F36: ● | H36: 분기 | I36: 부하 구간별 | J36: "동일 부하에서 정류 손실 +0.6%p." | K36: [33] 추정
A37: 수전해(PEM) | B37: 밸브 | C37: 자동차단밸브 개폐횟수 | D37: 누적 개폐횟수 대비 제조자 한도 | E37: ● | H37: 월 | I37: 카운터 | J37: "V-101 개폐 한도 대비 78%. 85% 경보 도달 예상 5개월 후." | K37: [40]
A38: 수전해(PEM) | B38: 스택 | C38: 잔여수명·교체 시점 | D38: 열화율, 운전시간 예측, 수명말 기준(+10% 전압) | G38: ● | H38: 연 | I38: 1년 이상 | J38: "현 열화율·운전 패턴 유지 시 수명말 도달 2035년(추정). 교체비는 CAPEX의 35~45% 수준." | K38: [32][34]
A39: 압축·저장·안전 | B39: 압축기 | C39: 비소비전력(kWh/kg)·체적효율 지수 | D39: 전력, 유량, 흡입·토출 압력·온도 | E39: ● | H39: 월(압력비 구간별) | I39: 1분, 기준점 수백 h(추정) | J39: "동일 압력비에서 kWh/kg +7%. 내부 누설 의심." | K39: [46] 방법은 추정
A40: 압축·저장·안전 | B40: 압축기 | C40: 단별 토출온도·단간 압력비 | D40: 단별 온도·압력 | E40: ● | H40: 월 | I40: 1분 | J40: "2단 토출온도가 기대치 대비 +12°C. 2단 밸브 누설 의심." | K40: 추정
A41: 압축·저장·안전 | B41: 압축기 | C41: 다이어프램 상태 | D41: 동적 오일압, 오일 온도 | E41: ● | H41: 월(추세), 이상은 즉시 | I41: 오일압은 현장에서 요약값 산출 | J41: "오일압 파형 지표 기준 대비 이탈 증가. 다이어프램 점검 앞당김 권고." | K41: [48]
...

Sheet 정기 리포트 구성
A1: 정기 분석 리포트 표준 구성
A2: 월간 리포트가 업계 모범사례 주기이며, 분기는 월간 요약+추세, 연간은 계약 KPI·열화·교체계획을 담습니다. 수시 리포트는 1% 초과 손실·안전 이벤트 등으로 발행합니다.
A3: 주식회사 퍼스트씨앤디 · 작성일 2026. 09. 17
A5: 리포트 | B5: 섹션 | C5: 내용 | D5: 출처
A6: 월간 | B6: 1. 요약 | C6: 발전량·수소 생산·연료전지 발전 대 예산·기대치, 주요 이슈 3개, 조치 요청 | D6: [11]
A7: 월간 | B7: 2. 원자료·데이터 품질 | C7: 일사량, 발전·소비 전력량, 결측·센서 이상 표시, 결측 처리 방법 명시 | D7: [11][12]
A8: 월간 | B8: 3. PV 성능 KPI | C8: PR(최소), 온도보정 PR·EPI(모범사례), 기준·비발전량, 인버터별 분해 | D8: [10][11]
A9: 월간 | B9: 4. 가용률 | C9: 기술·계약·에너지 가용률, 외부요인 제외 명시(IEC 61724-3 취지) | D9: [8][10]
A10: 월간 | B10: 5. 손실 분해 | C10: 출력제어, 트립·정지, 오염, 클리핑, 온도, 기타 잔차 | D10: [3][6][23]
A11: 월간 | B11: 6. 알람·고장 | C11: 대형 사고·생산영향, 고장간격, 응답·조치·해결 시간 | D11: [10][11]
A12: 월간 | B12: 7. ESS | C12: RTE, 완전사이클·DOD, SOC 창 준수, 온도 이력, 셀 편차 이상, 절연·보호 이벤트 | D12: [26][27][30]
A13: 월간 | B13: 8. 전해조 | C13: 운전시간·기동정지·OCV 대기, 비소비전력(부하 구간별), 가용률, 순도·전도도, 밸브 개폐 누적 | D13: [32][37][39][40]
A14: 월간 | B14: 9. 압축·저장·안전 | C14: 압축기 kWh/kg, 운전·정비, 검지기 드리프트·경보, 누설 판정 | D14: [41][46]
A15: 월간 | B15: 10. 연료전지 | C15: 효율·수소원단위, 기동정지·부하변동, 정지 간 평균 운전시간·가용률 | D15: [50][53][54]
A16: 월간 | B16: 11. 정비 이력 | C16: 예방정비 계획 대비 실행(연간정비계획 편차·사유), 교정정비 내역, 예방:교정 비율(모범 80:20) | D16: [9][10]
... A37: 수시 | B37: 수소 누출 경보·비상정지 | C37: 비상대응·점검기록, 원인 규명 후 재가동 | D37: [39][41]

Sheet AI 분석 방법
A1: AI 분석으로 얻는 결과와 개선 방향
A2: 성숙도: 기술(현황)→진단(원인)→예측(수명)→처방(최적화). 정량 근거는 원 출처 기준이며 '검증 결과' 시트에서 대조 결과를 확인하세요. 마지막 2행(‘AI 설명’·‘리포트 문장 다듬기’)은 실제로 구현된 LLM 층이며, 수치는 통계 엔진이 만들고 LLM은 문장만 다시 씁니다. 출처 대조에서 반박·미확인으로 판정된 수치는 정정하거나 삭제했습니다.
A3: 주식회사 퍼스트씨앤디 · 작성일 2026. 09. 17
A5: 분야 | B5: 분석 | C5: 답하는 현장 질문 | D5: 입력 데이터 | E5: 방법 | F5: 결과물 | G5: 개선·코칭 | H5: 정량 근거 | I5: 필요 데이터 조건 | J5: 성숙도 | K5: 난이도
A6: 태양광 | B6: 물리 기반 기대발전량 모델과 손실 분해(워터폴) | C6: 이 발전소는 정상이라면 얼마를 발전했어야 하고, 부족분은 어디서 생겼나(오염·열화·음영·클리핑·출력제어·정지·기타)? | D6: POA·모듈온도·외기온·풍속(또는 위성 일사) 설계 정보(모듈 온도계수, 스트링 구성, 인버터 효율·정격) AC/DC 전력, 상태코드, 출력제한 설정 강수·세척 기록 | E6: 물리+ML 하이브리드. ① pvlib로 POA → 셀온도(Sandia/PVsyst 모델) → DC 전력(PVWatts 또는 1-다이오드) → 인버터 효율·클리핑을 계산한다. ② 실측과의 잔차에서 모드별 손실을 규칙으로 할당한다(정지=상태코드, 출력제한=설정·동시성, 클리핑=정격 평탄, 오염=SRR 추정분). ③ 설명되지 않는 잔차는 그래디언트 부스팅(LightGBM)으로 보정해 체계적 모델 오차(스펙트럼·저일사·IAM)를 학습하고, 남은 잔차를 '미분류 손실'로 둔다. | F6: 사이트·인버터별 일/월 에너지 워터폴(기대 kWh → 각 손실 kWh·₩ → 실측 kWh), 미분류 손실 비율, 데이터 품질 등급 | G6: 손실을 원 단위로 정렬해 조치 우선순위를 정하는 코칭 리포트의 뼈대가 된다. '이번 달 3.2%p 손실 중 1.8%p는 3번 인버터 정지, 0.9%p는 오염'처럼 설명하는 문장을 LLM이 생성할 입력이 된다. | H6: 정량 근거 미확인(방법론 표준화 단계). 참고로 업계 보고서는 설비 기인 손실이 2025년 평균 5.08%라고 보고했다(Raptor Maps 2026, PV Tech). 이 크기의 손실을 분해해 회수하는 것이 목표. | I6: 1분~15분 해상도, 최소 3개월(계절 보정은 1년 이상). 일사계 교정·청소 기록, 스트링 맵, 모듈 데이터시트 필수. 상태코드와 출력제한 이력이 없으면 손실 분해 신뢰도가 크게 떨어진다. | J6: 진단(원인) | K6: 중간
A7: 태양광 | B7: 비가역 열화율 추정(RdTools YoY)과 기술별·보증 대비 벤치마크 | C7: 모듈이 연간 몇 %씩 늙고 있으며, 보증 곡선과 동일 기술 피어 대비 빠른가? | D7: 온도·일사 정규화 발전량(일 집계) 위성/청천 모델 일사(센서 드리프트 교차검증) 준공일, 셀 기술, 보증 곡선 | E7: 통계. RdTools 워크플로(정규화 → 필터 → 일 집계 → Year-on-Year 쌍 변화율 분포의 중앙값 → 부트스트랩 신뢰구간)를 쓴다. 센서 기반과 청천(clear-sky) 기반 결과를 교차 비교한다. 오염이 강하면 CODS(열화·오염·계절성 동시 추정)를 적용한다. 사이트 간에는 계층 베이지안으로 기술·기후별 분포를 추정한다. | F7: 사이트/인버터별 열화율(%/yr) ± 신뢰구간, 보증 대비 초과 여부, 피어 백분위 | G7: 열화가 보증을 넘으면 IV 스캔·EL로 증거를 수집해 보증 청구로 연결한다. PID 의심 시 음극 접지·야간 PID 복구 설정을 적용한다. 리파워링·모듈 교체 시점을 판단하는 입력이 된다. | H7: NREL PV Fleet(1,700개 시스템, 7.2GW) 중앙 PLR −0.75%/yr, 서늘한 기후 −0.48, 더운 기후 −0.88%/yr(Jordan et al. 2022). YoY 방식은 센서 드리프트·데이터 이동·오염에도 강건하다(Jordan et al. 2018). | I7: 최소 2년(권장 3년 이상) 연속 데이터, 일 집계 가능한 해상도(1시간 이상). 일사계 교체·교정 이력, 인버터 교체 이력(단절점). | J7: 진단(원인) | K7: 낮음
A8: 태양광 | B8: 오염 손실 추정과 경제적 세척 최적 시점 | C8: 지금 오염으로 하루 얼마를 잃고 있으며, 언제 세척하면 비용 대비 이익이 최대인가? | D8: 일 단위 온도보정 PR 또는 기대 대비 실측비 강수량(≥1mm 세정 이벤트)·황사·미세먼지 세척 기록·단가, SMP+REC 단가 발전량 예보(향후 기대 일사) 오염 측정소(있으면) | E8: 통계+최적화. ① RdTools SRR로 강우 사이 오염률(%/day)과 현재 오염비를 추정한다. ② 향후 오염 누적(계절별 오염률 분포)과 강우 확률(기상예보)을 몬테카를로로 시뮬레이션한다. ③ 기대 손실액 − 세척비가 최대가 되는 세척일을 동적계획법이나 임계 규칙(누적 손실액 ≥ 세척비)으로 산출한다. | F8: 사이트별 현재 오염 손실(%·₩/일), 권장 세척일과 기대 순이익, 강우 대기 권고 여부 | G8: 일괄 정기 세척을 데이터 기반 선택 세척으로 바꿔 세척비를 줄이고 손실을 회수한다. 황사 직후·장기 무강우 시에만 선택 세척을 권고한다. | H8: 스페인 1MW 사이트(연 오염 손실 3% 이내 지역)에서도 세척 일정 최적화로 이익이 최대 3.6% 증가했다(Micheli et al., Energy 2021). 전 세계 오염 손실은 2018년 연 발전량의 최소 3~4%, 30~50억 유로로 추정된다(IEA PVPS T13-21:2022). | I8: 일 집계 PR 1년 이상(계절 오염률), 강수 일자료, 세척 기록 필수(없으면 회복 이벤트를 강우로 오인). 불균일 오염은 드론 가시광/IR로 보완. | J8: 처방(최적화) | K8: 중간
A9: 태양광 | B9: 스트링·인버터 고장 자동 분류(규칙 + 지도학습) | C9: 성과가 떨어진 원인이 스트링 개방·다이오드 단락·PID·음영·오염·인버터 이상 중 무엇인가? | D9: 스트링 전류비·MPPT 전압비 시계열 기대 대비 잔차(시각×일자 히트맵) Riso·잔류전류·AFCI 이벤트·고장코드 정비기록 라벨(조치 결과) | E9: 규칙 + ML 하이브리드. 1차로 물리 규칙(전류비<0.1 개방, 전압 1/3모듈 계단 = 다이오드, 저일사 PR 선행 하락 + 전압 하락 = PID 등)을 적용한다. 2차로 시계열 특징(tsfresh 계열: 계단 크기·지속·시각 대칭성·습도 상관·일사 의존성)을 추출해 그래디언트 부스팅·랜덤포레스트 다중 분류기를 학습한다. 라벨이 부족하면 은닉 마르코프 모델(HMM) 같은 비지도 군집으로 상태를 발견한 뒤 정비기록으로 명명한다(Sandia Hopwood et al. 2022 접근). | F9: 이상 에피소드별 고장 유형 확률, 근거(특징값·기준선), 추정 손실 kWh, 권장 점검 방법(IV 스캔/IR/현장) | G9: 출동 전 원인 후보와 필요 부품·장비를 알려 1회 출동 해결률을 높이고 MTTR을 줄인다. 오탐 억제(센서·통신·출력제어·날씨 우선 판정). | H9: SunEdison 450개 시스템 27개월 3,600건 티켓 분석에서 인버터가 고장 빈도·에너지 손실 모두 1위였고, 에너지 손실의 50%가 사건 5%에서 나왔다(Golnas, IEEE PVSC 2012). 긴 정지를 빨리 잡는 것이 핵심이다. 분류기 정확도의 현장 정량 근거는 미확인. | I9: 스트링 전류 1~5분, 최소 수 개월 + 라벨된 조치 기록 수백 건 이상(추정). 스트링 맵 정확성 필수. | J9: 진단(원인) | K9: 중간
A10: 태양광 | B10: IV 커브 형상 기반 결함 진단 | C10: IV 곡선 모양으로 볼 때 이 스트링의 손실은 오염·열화·직렬저항·션트·다이오드·음영 중 무엇 때문인가? | D10: IV 곡선 점 배열 스캔 시 POA·모듈온도 모듈 데이터시트·직렬 수 이전 스캔(베이스라인) | E10: 물리+ML. ① STC 환산(IEC 60891) 후 1-다이오드 파라미터(Iph, I0, n, Rs, Rsh)를 적합한다. ② Isc비·Voc비·FF비·계단 수·Rs/Rsh 변화 특징으로 규칙 분류를 한다. ③ 곡선 자체를 1D-CNN 또는 이미지화 CNN으로 분류한다(학습 데이터는 Sandia pvOps IV 시뮬레이터로 결함 합성 곡선 증강). | F10: 스트링별 결함 유형·심각도, STC 환산 Pmax 손실(%), 스트링 순위표 | G10: 수천 스트링 중 조치할 스트링만 골라 현장 작업을 집중한다. 보증 청구용 정량 증거를 확보한다. | H10: 한국에너지기술연구원: I-V 곡선 + 패널·어레이 정보 + 환경센서 기반 AI로 오염·성능 저하를 95% 이상 정확도로 판단(2023, 인더스트리뉴스). 화웨이(제조사 주장): 100MW 15분 스캔·14종 결함, 말레이시아 9,496 스트링 중 12.1% 결함, 전량 조치 시 발전량 1.5% 이상 증가. | I10: 인버터 내장 스캔 기능 또는 휴대형 트레이서. 청천·안정 일사(>600 W/m² 권장, 추정) 조건. 월~분기 주기, 결함 라벨 수백 곡선 이상. | J10: 진단(원인) | K10: 중간
A11: 태양광 | B11: 드론 열화상(IR)·가시광 이미지 결함 검출과 발전데이터 결합 우선순위화 | C11: 어느 모듈이 어떤 결함(핫스팟·서브스트링·다이오드·PID 패턴·오염·스트링 개방)을 갖고 있고, 무엇부터 고쳐야 하나? | D11: 방사측정 IR 정사영상, 가시광 영상 촬영 시 POA·풍속·외기온 배치도(GIS)·스트링 맵 동일 기간 스트링 전류비·손실 추정 | E11: 딥러닝. ① 모듈 분할(세그멘테이션: U-Net/Mask R-CNN) 후 결함 검출·분류(YOLO 계열 또는 EfficientNet)를 한다. ② ΔT를 표준 일사로 환산하고 IEC TS 62446-3 이상 등급을 매핑한다. ③ 결함 좌표를 스트링 채널에 조인해 SCADA 손실과 교차검증한다(원격에서 보이는 손실 + IR 확인 = 높은 신뢰). ④ 손실 ₩ × 안전위험(화재) 가중으로 조치 순위를 매긴다. | F11: 결함 목록(좌표·유형·ΔT·등급·추정 손실·안전등급), 작업지시 초안, 전년 대비 결함 증감 | G11: 전수 점검을 1년 1회 이상 저비용으로 수행하고, 화재 위험(정션박스·커넥터 과열)을 선제 제거한다. 점검 빈도를 늘릴수록 손실이 줄어드는 경향이 있다. | H11: 폴란드·스페인 연구(Measurement, 2026): 자동비행 + AI 분석으로 점검·판독·보고 147분 → 54분(−63.3%), EfficientNet-B0 가중 F1 0.927(AI타임스 보도). Raptor Maps(업계): 연 5회 점검 사이트 평균 손실 약 3% vs 연 1회 약 7%(상관관계, 인과 아님). | I11: IR 해상도 640×512급 이상, POA>600 W/m² 청천·약풍(IEA PVPS T13-10), 좌표 정합(RTK/GCP). 연 1~2회 + 이상 의심 시. 국내는 비행 승인 등 규제 확인 필요. | J11: 진단(원인) | K11: 높음
A12: 태양광 | B12: EL 이미지 셀 결함 분류 | C12: IR·원격 분석으로 의심된 모듈에서 셀 크랙·PID·납땜 불량이 얼마나 진행됐나, 보증 대상인가? | D12: EL 이미지(야간 전류 인가 또는 주간 PL/EL) 모듈 모델·출하 EL(있으면) | E12: 딥러닝. 모듈 원근 보정·셀 분할 후 셀 단위 CNN 분류(정상/크랙/비활성/PID)를 한다. 라벨이 적으면 사전학습 모델 미세조정과 SVM(특징 기반) 경량 모델을 병행한다. | F12: 셀별 결함 확률·유형, 모듈 비활성 면적 %, 출하 대비 변화 | G12: 보증 청구·제조사 협상 근거, 모듈 교체 범위 결정, 시공·운송 결함 원인 규명. | H12: Deitsch et al.(Solar Energy 2019): 1,968개 셀 EL 이미지로 CNN 평균 정확도 88.42%(GPU 필요), SVM 82.44%(범용 하드웨어). | I12: 고해상도 EL(셀당 충분한 픽셀), 야간 전원장비. 수작업 야간 EL은 하룻밤 약 0.2MWp(IEA PVPS T13-10)라 표본 점검용. 셀 라벨 수천 장 수준(추정). | J12: 진단(원인) | K12: 높음
A13: 태양광 | B13: 인버터 고장 예지(PHM) | C13: 어느 인버터가 향후 수 주~수 개월 내 고장 날 가능성이 높고, 무엇(팬·IGBT·커패시터·절연·통신)이 원인일까? | D13: 방열판−외기 ΔT(부하 bin), 디레이팅 빈도 효율 bin 추세, 고장코드 빈도·종류 Riso·잔류전류 추세 가동연수·모델·펌웨어, 정비·교체 이력 | E13: 통계+ML. 건전성 지표(HI)를 정의하고(동일 조건 bin 대비 편차의 EWMA), 생존분석(Cox 비례위험, 랜덤 생존 포레스트)으로 고장까지 시간 위험도를 추정한다. 코드 시퀀스는 이벤트 시퀀스 모델(마르코프·LSTM)로 전조 패턴을 학습한다. 동일 모델 피어가 많을수록 유리하다. | F13: 인버터별 30/90일 고장 위험도, 의심 부품, 권장 예방정비(팬·필터 교체, 체결 점검), 예비품 수요 | G13: 고장 후 출동을 계획 정비로 바꿔 정지 시간과 긴급 출동비를 줄이고, 여름 전 팬·필터를 선제 교체한다. | H13: Sandia·NREL·EPRI: 800여 사이트 5.5만 건 정비기록 ML 분석에서 통신, 지락, 열관리, IGBT가 가장 빈번한 인버터 하위계통(IEEE Access 2020). 선행 탐지 기간의 정량 근거는 미확인. | I13: 동일 모델 수십 대 이상, 2년 이상 온도·코드 데이터, 고장·교체 이력 라벨 필수(라벨이 가장 큰 병목). | J13: 예측(수명) | K13: 높음
A14: 태양광 | B14: 발전량 예측(익일·당일) | C14: 내일·몇 시간 뒤 사이트별 발전량은 얼마인가(시장 입찰·예측제도 정산, 수전해 운전계획용)? | D14: 수치예보(기상청 LDAPS/동네예보 등)·위성 일사 과거 실측 발전량·출력제어 이력 설비 정보(용량·방위·경사·ILR) 최근 오염·열화 상태 | E14: 물리+ML. 예보 일사 → pvlib 물리 모델 기대발전량을 기저 특징으로 두고 LightGBM/Transformer로 오차를 보정한다(사이트·시각·계절 임베딩). 당일은 위성 구름 이동 기반 초단기 예측. 분위수 회귀로 불확실성 구간 제공. | F14: 사이트·권역별 시간 단위 발전량 예측과 P10/P50/P90, 예측오차율 추적 | G14: KPX 재생에너지 발전량 예측제도 정산금 수익, 출력제어 대비, 연계 수전해·ESS 운전계획(잉여전력 → 수소 생산 스케줄) 최적화. 실측 대비 예측 편차는 고장 조기 신호로도 쓴다. | H14: 정산 구간(2025.7 기준, 해줌 블로그): 오차율 4% 이하 4원/kWh, 4~6% 3원/kWh. 1MW 약 연 330만 원 추가 수익 예시(업계 자료, 확인 필요). 모델 정확도의 공공 정량 사례는 이번 조사에서 미확인. | I14: 1시간(가능하면 15분) 실측 1년 이상, 과거 예보 아카이브(학습용), 출력제어 구간 라벨. | J14: 예측(수명) | K14: 중간
A15: 태양광 | B15: 정비기록·알람 구조화(NLP/LLM)와 발전소별 코칭 리포트 생성 | C15: 흩어진 작업지시·메모·알람을 표준 고장 분류로 정리하고, 사이트별로 무엇을 먼저 해야 하는지 쉽게 설명할 수 있나? | D15: 정비기록 자유 텍스트, 작업지시 고장코드·이벤트, 탐지 결과(Finding: 유형·근거·손실·심각도) 손실 워터폴, 비용·단가 | E15: LLM + 규칙. ① LLM 추출로 텍스트를 (자산, 증상, 원인, 조치, 부품, 소요시간) 구조로 만든다(Sandia pvOps 텍스트-시계열 결합 방식 참고). ② 결과를 시계열 이벤트와 시간 조인해 라벨 DB를 만든다. ③ 리포트는 구조화 Finding만 입력으로 받는 템플릿 제약 생성(RAG: 제조사 매뉴얼·표준 절차)을 쓰고, 수치는 원본 인용을 강제해 환각을 방지한다. | F15: 표준화된 고장·조치 DB, 사이트별 월간 코칭 리포트(Top-N 조치, 기대 회수 kWh·₩, 근거 그래프 링크), 반복 고장 인사이트 | G15: ML 모델 학습 라벨을 자동 축적하고(선순환), 경영진용 요약과 엔지니어용 근거를 한 번에 제공한다. 조치 후 효과를 다시 측정해 권고 품질을 개선한다. | H15: Sandia·NREL: 5.5만 건 정비기록을 ML로 분류해 빈발 고장 모드 도출(IEEE Access 2020). 리포트 자동화의 정량 효과는 미확인. | I15: 정비기록 수백~수천 건, 코드 사전, 자산 ID 일관성. 개인정보·업체명 마스킹. | J15: 처방(최적화) | K15: 중간
A16: 태양광 | B16: 클리핑·출력제어·설정 손실 정량화와 설계·설정 최적화 | C16: 클리핑과 출력제어로 잃는 전력량은 얼마이며, ILR·역률·Volt-Var·출력제한 설정을 바꾸면 얼마나 회수되나? | D16: 1분 AC/DC 전력, V_dc 출력제한 설정·지령 이력, 무효전력 설정 기대 DC 전력(물리 모델) SMP·REC 단가 | E16: 물리+통계. 클리핑 구간 검출(PVAnalytics)과 기대 DC − 실제 AC로 손실을 산정한다. 출력제어는 지령·동시성으로 분리한다. 시뮬레이션(pvlib)으로 ILR·설정 대안의 연간 손익을 비교한다. 계통 전압 상승 트립 사이트는 Volt-Var 적용 시 트립 감소 대비 유효전력 손실을 추정한다. | F16: 사이트별 클리핑·출력제어·디레이팅 손실 kWh·₩, 설정 오류(잔존 제한) 경보, 증설(DC 추가)·ESS·수전해 연계 시 흡수 가능량 | G16: 설정 잔존 즉시 해소, 반복 전압 트립 사이트의 무효전력 설정 조정, 버려지는 클리핑·출력제어 전력을 수전해·ESS로 돌리는 사업 판단 근거. | H16: 정량 근거 미확인(사이트 의존). 국내 출력제어 증가(기존 리서치: 2024년 육지 15회, 2025년 4월말까지 20회)로 가치가 커지는 영역. | I16: 1분 해상도 필수(15분 평균은 클리핑 과소평가), 지령 로그, 설정 스냅샷. | J16: 처방(최적화) | K16: 낮음
... A136: LLM·코칭 | B136: 코칭 리포트 문장 다듬기 | C136: 월간·분기 리포트 초안을 사람이 읽기 좋게 쓸 수 있는가 | D136: 리포트 초안 섹션 문장 발견사항·조치 이력·KPI 값 금지 표현 목록 | E136: 리포트 초안 검증 규칙(숫자 토큰·방향 단어·금지 표현)을 그대로 쓰되 쉬운 말 4줄용으로 넓혔다. 검토자가 승인하기 전에는 초안 상태로 남고, PDF 출력은 승인 후에만 된다 | F136: 검토 대기 상태의 리포트 초안 | G136: 검토자가 문장을 고치는 시간을 줄인다. 수치·판정은 바뀌지 않으므로 검토는 표현만 보면 된다 | H136: 생성문이 숫자를 하나라도 바꾸면 채택하지 않는다(검증 규칙 ①) — 리포트 수치의 출처는 항상 분석 엔진이다 | I136: 발견사항과 KPI가 먼저 계산돼 있어야 한다 | J136: 기술(현황) | K136: 중간

Sheet 개선항목·기대효과
A1: 개선 여지와 기대효과
A2: 정량 효과는 출처 조건 기준입니다(사이트 조건에 따라 달라짐).
A3: 주식회사 퍼스트씨앤디 · 작성일 2026. 09. 17
A5: 영역 | B5: 개선 항목 | C5: 기대효과(출처 기준) | D5: 필요 분석·주기 | E5: 출처
A6: PV | B6: 조건기반 세척 최적화 | C6: Micheli 2021: 스페인 남부 1 MW(연 오염손실 3% 이내 지역), 여름 ±31일 창 안 연 1회 최적 세척 시 이익 최대 3.6%. 세척비 $0.25~1/m², 물 약 1 L/m². 오염 영향 시스템의 연간 손실 중앙값 2~3%. 전 세계 손실 최소 3~4%(2018). 국내 황사로 단기 2% 이상 출력 감소 관측 | D6: 월(알림), 연(최적화). 한국은 황사·꽃가루·장마 계절성 반영(추정) | E6: [3][7][8][22]
A7: PV | B7: 인버터 가용률 개선(트립 원인 제거·예비품) | C7: 미국 설비군 가용률 중앙값 0.99 대 하위 10% 0.95 → 하위권 설비를 중앙값으로 올리면 +4%p(계산). 계약가용률 최소 98% 모범사례 | D7: 월(트립 통계), 분기(반복 원인) | E7: [3][10][19]
A8: PV | B8: 필터·팬 정비로 인버터 열 스트레스 저감 | C8: 전해 커패시터 수명은 10°C 낮출 때마다 2배. 필터 청소 반기·교체 2년 | D8: 분기(방열 온도차 추세) | E8: [9][20]
A9: PV | B9: 출력제어·계통 손실 분리 | C9: 육지 출력제어 2025년 4월 말까지 20회(2024년 연 15회) → 설비 손실 과대평가 방지 | D9: 월 | E9: [23]
A10: PV | B10: 일사계 품질관리 | C10: 오염·미교정 일사계는 위성보다 부정확 → PR 오판 방지(정성). Class A는 주 1회 세척, 2년 교정 | D10: 월(드리프트) | E10: [8][13]
A11: ESS | B11: SOC 창·DOD 운용 | C11: LFP 사이클 수명 4,800(100% DOD) → 8,000(60%) → 32,000(30%). 완전사이클 처리량은 60%까지 같고 30%에서 2배. 안전상 SOC 옥내 80%·옥외 90% 제한 | D11: 월(준수), 연(수명 영향) | E11: [25][30]
A12: ESS | B12: 온도 관리(공조 최적화) | C12: 캘린더 열화는 온도에 강하게 의존. 조건 차이로 80% 도달 시간이 수천 시간 차이. 셀 온도를 연중 20~30°C로 유지하면 수명 4.9년→7.0년(NREL Smith 2017 수명모델, 용량 70% 기준·DOD 74%, 시뮬레이션) | D12: 월(온도 이력), 분기(용량 추세) | E12: [28][29]
A13: ESS | B13: 초기 2년 이상 감시 강화(제어·주변설비 중심) | C13: 고장 72%가 시공·시운전·운전 2년 내, 원인 분류 26건 중 셀 직접 원인 3건(11%). 절연 급락이 전조 | D13: 월(초기 2년 강화) | E13: [27][30]
A14: 전해조 | B14: 정지 중 OCV 회피(보호전위·미소전류) | C14: OCV 사이클 718회 후 고주파저항 약 1.6배. 1.3 V 유지 시 500회 동안 열화 없음. 필요 전류는 최대전력의 1%보다 훨씬 작음 | D14: 월(OCV 대기시간), 분기(전압 추세 전후 비교) | E14: [36]
A15: 전해조 | B15: 기동정지 감소(대기운전 활용) | C15: 알칼라인 사례: 4~6 h 정지는 수명손실 없음, 기동정지 5,000회 제한 예. 스택 교체비가 CAPEX의 35~45%라 수명 연장 가치 큼. 밸브 개폐 한도 85% 경보·90% 기동금지 | D15: 월(횟수), 연(수명 예측) | E15: [34][40]
A16: 전해조 | B16: 부하 운용(정류기 효율·다스택 분담) | C16: 정류기 효율은 15~20% 부하 미만에서 낮고, 시스템 효율은 약 30% 부하에서 최고 | D16: 월(부하 구간별 kWh/kg) | E16: [33]
... A23: 공통 | B23: 교체 적립금 산정(Weibull) | C23: 인버터 교체는 플랜트 수명 중간쯤. PCS 10년 대정비(전력설비 비용 30%) | D23: 연 | E23: [8][12][25]

Sheet 축적기간별 로드맵
A1: 데이터 축적 기간별로 가능해지는 분석
A2: 초기 1~2년은 고장 집중 구간이므로 열화 판정보다 이상·결함 탐지에 비중을 둡니다.
A3: 주식회사 퍼스트씨앤디 · 작성일 2026. 09. 17
A5: 시점 | B5: 가능해지는 분석 | C5: 아직 불가·주의 | D5: 근거
A6: 0~3개월(시운전 직후) | B6: 데이터 품질 게이트(결측·범위·고착·교정 이력). 월 발전량 대 기대치, PR·온도보정 PR(2주~1개월). 가용률·트립·알람 통계. 출력제어 분리. ESS 사이클별 RTE(완전 충방전 1회 이상). 전해조 비소비전력(부하 구간별), 운전·기동정지·OCV 대기 집계. 연료전지 효율·정지 간 평균 운전시간. 압축기 kWh/kg 기준점. 법정·교정 캘린더. 이 시기 부하·온도 구간별 기준값을 저장 | C6: PV 열화율, ESS 수명, 스택 열화율 판정 금지. 전해조는 초기 1,000 h 활성화 구간이 끝나야 성능 기준점을 잡음. PV 가용률은 첫 6개월 저조 경향 | D6: [3][10][26][32][38]
A7: 3~6개월 | B7: 동종 비교(인버터·스트링·랙) 이상 탐지 안정화. 첫 오염 구간 분석(14일 이상 건조구간, 봄 황사·꽃가루). 인버터 효율·방열 추세 초안. ESS 셀 편차·온도 추세, 용량 잠정 추세. 전해조 운전 1,000 h 이후 기준점 설정. 연료전지 전압 추세 초안. 반복 고장 근본원인 | C7: ESS 용량은 월 0.25%p(계산)라 계측 분해능과 겹침. 계절 효과 미분리 | D7: [6][22][25][38]
A8: 6~12개월 | B8: 여름 고온·장마 포함 계절 1주기 → 온도·공조 영향 분리. 오염·세척 비용편익 1차 최적화. 첫 연간 리포트(연간 PR·계약가용률). ESS 분기 용량 추세와 온도 영향. 전해조 첫 1,000 h 구간 열화율(태양광 연계 시 약 6개월 운전, 계산). 연료전지 분기 열화 추세. 압축기 신뢰성 통계·정비 비계획 비율 | C8: PV YoY 불가(24개월 필요). 스택 잔여수명은 불확실성 큼 | D8: [3][6][10][38][46]
A9: 12~24개월 | B9: 전년 동월 비교 가능(기상보정). 전해조·연료전지 연간 열화율 확정 및 목표·보증 대비 평가. ESS 연간 수명 추세와 보강 시점 1차 예측. 첫 법정 정기검사 결과 반영(수소·ESS 1년). 개선과제 전후 효과 검증(OCV 회피, 세척 주기) | C9: 24개월 시점에야 PV YoY 첫 추정(신뢰구간 넓음). ESS 고장 집중 구간(2년) 종료 전 | D9: [3][4][27][31][32][42][43]
A10: 24~36개월 | B10: PV YoY 열화율 첫 산출(오염 영향 분리 방법 병행). 보증 선형 열화 대비 평가. 인버터 고장간격 초기 추정 | C10: 신뢰할 수 있는 PV 열화율은 3~5년 필요 | D10: [3][4][5][15]
A11: 3~5년 이상 | B11: 신뢰도 높은 PV 열화율. Weibull 교체 예측·적립금. ESS 급락점 탐지, 보강·교체 의사결정. 스택 교체 시점 확정. 인버터 수명 중간 교체 준비. PCS 10년 대정비 계획. 법정 재검사(압력용기 4년, 용기·탱크 5년)와 정비계획 통합 | C11: 급락점은 사이클 후반에 나타나 장기 데이터 필요 | D11: [4][8][12][25][29][44]

Sheet 검증 결과
A1: 리서치 주장 출처 대조 결과
A2: 검증 에이전트가 출처 URL을 직접 열어 수치·조건을 대조했습니다. 반박·부분 확인 항목은 '출처 기준 문장'을 사용하세요.
A3: 주식회사 퍼스트씨앤디 · 작성일 2026. 09. 17
A5: 분야 | B5: 판정 | C5: 원 주장 | D5: 출처 기준 문장 | E5: 비고 | F5: 근거 URL
A6: 태양광 | B6: 반박 | C6: N형 TOPCon 모듈(JinkoSolar Tiger Neo)의 Pmax 온도계수는 −0.29%/°C, 양면율은 80±5%이다(데이터시트). HJT는 약 −0.24%/°C, PERC는 약 −0.35~−0.38%/°C 수준(추정 범위)이다. | D6: JinkoSolar Tiger Neo 3.0 페이지 기준 Pmax 온도계수는 −0.26%/°C, 양면율은 85±5%이다. HJT(약 −0.24%/°C)·PERC(약 −0.35~−0.38%/°C)는 이 출처에서 확인되지 않은 추정 범위다. | E6: 인용 URL은 Tiger Neo 3.0 페이지인데 −0.29%/°C·80±5%는 이전 세대 값으로 보임. 제품 세대와 데이터시트 모델명을 명시해야 함. | F6: https://www.jinkosolar.com/en/site/tigerneo_3
A7: 압축·저장·안전 | B7: 반박 | C7: 단열압축 25 °C·압력비 3 토출 약 137 °C, API 618은 수소 계열 토출온도를 135 °C로 제한 | D7: 이상기체 단열압축(k≈1.41) 기준으로 수소를 25 °C에서 압력비 3으로 압축하면 토출온도는 약 137 °C다(계산값). API 618 6판은 일반 예측 토출온도 한계를 135 °C로 두고, 수소 풍부 서비스(분자량 12 이하)나 무급유 실린더는 120 °C로 제한한다. | E7: 137 °C 계산은 맞다(137.2 °C). 그러나 EFRC 검토서 6.5.1절은 수소 풍부 서비스에 120 °C(250 °F)를 적용한다고 인용한다. '수소 계열 135 °C'는 틀렸고, 다이어프램 압축기 원리 항목에도 같은 오류가 있다. | F7: https://www.recip.org/wp-content/uploads/2025/05/EFRC-Report-Review-API-618-6th-edition-API-688-2nd-edition-Part-1-V1.pdf
A8: 압축·저장·안전 | B8: 반박 | C8: (사례) IJHE 2025/2016(일본·미국 비교): 비율 수치는 초록에 없음 | D8: IJHE 2025(Tzioutzios et al.)는 일본 KHK 사고 DB를 분석한 연구로, 초록 하이라이트에 누출의 1/3이 안전계통에서 시작됐고 누출 7건 중 1건은 사람이 발견했다는 비율이 있다. 주 누출원은 밸브·조인트·씰이며 디스펜서·압축기 관여가 가장 많았다. | E8: DOI 논문은 일본·미국 비교가 아닌 일본 단일 DB 연구이고, 초록에 비율 수치가 실제로 있다. 2016년 비교 연구는 URL이 없어 확인하지 못했다. | F8: https://doi.org/10.1016/j.ijhydene.2025.151309
A9: 상용 사례 | B9: 반박 | C9: SunEdison의 600여 PV 시스템 O&M 분석에서 인버터는 이슈 빈도와 에너지 손실 모두 1위였고, 에너지 손실의 50%가 전체 사건의 5%에서 발생했다. | D9: SunEdison의 PV 시스템 450개, 27개월(2010.1~2012.3) 서비스 티켓 3,600건 분석에서 인버터는 이슈 빈도와 에너지 손실 모두 1위였고, 에너지 손실의 50%가 전체 사건의 5%에서 발생했다. | E9: 분석 대상은 450개다. 슬라이드상 운영 규모는 750개 발전소 이상이며 '600여'는 어디에도 없다. ai_methods 그룹의 450개와도 다르다. | F9: https://pdfs.semanticscholar.org/7535/1afe78f698d9c94ea6f0e48183712c19a7d5.pdf
A10: 상용 사례 | B10: 반박 | C10: (사례) SINTEF 컨소시엄 (EU FCH JU, 2018~2021): 이탈리아·벨기에 운전원이 원격 시험 운전에 성공. 수소 생산단가 4~6유로/kg 분석. 가용률·열화 수치는 요약에 미공개. 예산 692만 유로. | D10: SINTEF 주관 HAEOLUS(EU FCH JU, 2018.1~2023.12, 총사업비 778만 유로·EU 지원 499만 유로): 노르웨이 Raggovidda 풍력단지에 2.5MW 전해조를 연계했고, 이탈리아·벨기에 운전원의 원격 운전을 시연했으며, 수소 생산단가를 4~6유로/kg으로 분석했다. | E10: 기간(2021→2023)과 예산(692만→총 778만/EU 499만 유로)이 CORDIS와 다르다. | F10: https://cordis.europa.eu/project/id/779469/reporting
A11: ESS | B11: 미확인 | C11: 모듈 단위 열전파 시험에서 NMC811 모듈은 표면온도 371.6°C에서 열전파가 시작된 반면 LFP는 첫 셀 열폭주가 436.6°C에서 발생했다. | D11: (미확인) 차량용 NMC-811(Mini Cooper SE)·LFP(Tesla Model 3 SR+) 모듈 열전파 비교 연구(eTransportation 2023)에서 NMC-811의 열폭주 반응 속도는 셀 에너지 기준 LFP보다 9배 빨랐다. 371.6°C·436.6°C 수치는 원문에서 확인하지 못했다. | E11: ScienceDirect 403으로 본문 확인 불가. 초록에는 해당 온도가 없음. 차량용 모듈 시험이라 정치형 ESS에 그대로 적용하면 안 됨. | F11: https://www.sciencedirect.com/science/article/pii/S2590116823000802
A12: ESS | B12: 미확인 | C12: (사례) TWAICE·InterEnergy(중미 40MWh BESS): 정량 복구량(MWh·%) 공개 자료 미확인 — 정성 사례(벤더 자료). | D12: (미확인) TWAICE·InterEnergy 고객 사례: 페이지 접근이 막혀 설비 규모와 정량 성과를 확인하지 못함. | E12: 403으로 확인 불가. 40MWh·중미 여부도 미확인이므로 보고서에서는 빼거나 '미확인'으로 표시. | F12: https://www.twaice.com/customer-stories/interenergy-bess-performance-issues-warranties-and-capacity
A13: 연계·계통 | B13: 미확인 | C13: (사례) Stadtwerke Mainz·Linde·Siemens·RheinMain 응용과학대: 2015년 9월 전력 432.5 MWh, 수소 72,526 Nm³, HHV 기준 이용효율 59.4%, 운전 146 h. 풍력 예측오차 흡수로 밸런싱 에너지 약 20% 감소. | D13: (미확인) Energiepark Mainz(IJHE 2017) 운전 수치는 논문 원문에 접근하지 못해 확인하지 못했다. | E13: Elsevier 유료벽으로 본문 확인 불가하고 초록 메타데이터도 없음. 사전 발표자료 수치이므로 보고서에서는 '미확인'으로 표시하거나 빼야 함. | F13: https://doi.org/10.1016/j.ijhydene.2016.12.145
A14: 연계·계통 | B14: 미확인 | C14: (AI효과) 출력제어 예측: 제주는 연 100회 안팎 출력제어가 발생했고, 2023년 4월부터 호남·영남 등 육지로 확대되었다(환경일보). | D14: (미확인) 제주 출력제어 연 100회 안팎, 2023년 4월 육지 확대 — 출처 URL이 없어 확인하지 못함. | E14: URL 미제공. KPX·산업부 자료로 횟수와 시점을 다시 확인해야 함.
A15: AI 공통 | B15: 미확인 | C15: McKinsey는 예지보전이 설비 정지시간을 30~50% 줄이고 설비 수명을 20~40% 늘린다고 제시한다(컨설팅 자료, 방법론 비공개). | D15: (원문 미확인) McKinsey 기사에 예지보전이 정지시간 30~50% 감소, 설비 수명 20~40% 연장을 가져온다는 서술이 있다고 알려져 있으나 확인하지 못했다. 보고서에는 '컨설팅사 추정, 원문 미확인'으로 표기한다. | E15: WebFetch 2회와 curl 모두 시간초과·연결 실패로 원문을 열지 못했다. 검색 예산도 소진돼 대체 출처를 찾지 못했다. | F15: https://www.mckinsey.com/capabilities/operations/our-insights/manufacturing-analytics-unleashes-productivity-and-profitability
A16: LLM·코칭 | B16: 미확인 | C16: (사례) Avangrid(Iberdrola 그룹) × AWS: 정량 효과 미공개(정량 근거 미확인) / First Time Right Autopilot, Amazon Bedrock, 2개 풍력단지 배치 | D16: (원문 미확인) Avangrid가 AWS 생성형 AI로 미국 풍력단지 정비를 지원하는 도구를 도입했다는 발표. 도구명·배치 단지 수·정량 효과는 미확인. | E16: WebFetch와 curl 모두 HTTP 403이라 열지 못했다. | F16: https://www.iberdrola.com/press-room/news/detail/avangrid-generative-ai-support-wind-farms-in-united-states
A17: 상용 사례 | B17: 미확인 | C17: (AI효과) 디지털 커미셔닝: TWAICE VERBUND 42MW 디지털 커미셔닝(2023, 정량 미공개) / (원리) Repsol 20MW/80MWh 보증 추적 사례 | D17: (출처 미제시) TWAICE의 VERBUND 42MW 디지털 커미셔닝, Repsol 20MW/80MWh 보증 추적 사례는 확인하지 못했다. | E17: 두 사례 모두 URL이 없고 웹 검색 예산이 소진돼 확인하지 못했다. | F17: https://www.accure.net/case-studies/imbalanced-racks-bring-commissioning-to-a-standstill
A18: 태양광 | B18: 부분 확인 | C18: 실리콘 태양전지의 개방전압(Voc)은 온도 1°C 상승당 약 2.2 mV 감소하고, 단락전류(Isc)는 일사량에 거의 비례한다. | D18: 실리콘 태양전지의 개방전압(Voc)은 온도 1°C 상승당 약 2.2 mV 감소하고, 단락전류(Isc)는 온도 상승 시 약 0.06%/°C로 소폭 증가한다(Isc의 일사 비례성은 이 페이지가 아닌 별도 출처로 뒷받침 필요). | E18: Voc −2.2 mV/°C 확인. 인용 페이지는 온도 영향 페이지라 'Isc가 일사에 비례'한다는 내용은 없음(물리적으로는 통설이나 출처 불일치). | F18: https://www.pveducation.org/pvcdrom/solar-cell-operation/effect-of-temperature
A19: 태양광 | B19: 부분 확인 | C19: EN 50530 시험에서 P&O와 증분 컨덕턴스(IncCond) MPPT의 효율 차이는 동적 0.13%, 정적 0.02%로 사실상 같고, 두 방식 모두 99% 이상의 효율을 보였다. | D19: EN 50530 시험에서 P&O와 증분 컨덕턴스(IncCond) MPPT의 효율 차이는 동적 0.13%, 정적 0.02%에 불과해 두 방식은 사실상 동등하다(Sera et al., IEEE J. Photovoltaics 2013). | E19: 차이 수치는 초록에서 확인. '둘 다 99% 이상'은 초록에 없고 본문 미확인이므로 삭제 또는 추정 표시 필요. | F19: https://vbn.aau.dk/en/publications/on-the-perturb-and-observe-and-incremental-conductance-mppt-metho/
A20: 태양광 | B20: 부분 확인 | C20: IEEE 1547-2018은 비의도적 단독운전 형성 후 2초 이내 검출·가압 중지·트립을 요구하며, 상용 인버터 대부분은 '임피던스 검출 + 양의 궤환' 계열 능동 검출법을 사용한다. | D20: IEEE 1547-2018은 비의도적 단독운전 형성 후 2초 이내에 가압 중지와 트립을 요구한다. 흔히 쓰이는 능동 검출법으로는 임피던스 검출, 양의 궤환 Sandia 주파수 편이(SFS), 임피던스 검출+양의 궤환 조합 등이 있으며, 제조사별 독자 방식도 쓰인다. | E20: NREL/TP-5D00-77782 원문에서 2초 요건 확인. '상용 인버터 대부분'이 특정 방식을 쓴다는 통계적 서술은 없음(각주: 'some common active methods include…', 제조사 독자 방식 가능). docs.nrel.gov 도메인은 접속 불가, docs.nlr.gov로 이전됨. | F20: https://docs.nlr.gov/docs/fy22osti/77782.pdf
A21: 태양광 | B21: 부분 확인 | C21: IEC/EN 62109-2 기반 비절연형 인버터의 잔류전류 감시장치(RCMU)는 30mA 이상 급변 또는 300mA 이상 연속 잔류전류에서 계통을 분리한다. | D21: SMA Sunny Boy Smart Energy 인버터는 IEC/EN 62109-2·VDE 0126-1-1에 따른 전극 감응형 잔류전류 감시장치(RCMU)를 갖추고, 잔류전류가 30mA 넘게 급변하면 계통에서 이중으로 분리한다(300mA 연속 기준은 이 매뉴얼에서 확인되지 않음). | E21: 30mA 급변 기준만 확인. 300mA 연속 잔류전류 기준은 IEC 62109-2 원문으로 따로 확인해야 함. 특정 제조사 매뉴얼을 일반 규칙처럼 서술함. | F21: https://manuals.sma.de/SBSExx-50/en-US/13316496907.html
A22: 태양광 | B22: 부분 확인 | C22: 스페인 1MW 사이트는 연 오염 손실이 2.8%에 불과했지만, 최적화된 세척 일정으로 이익이 최대 3.6% 증가했다. | D22: 스페인 남부 1MW 사이트처럼 연 오염 손실이 3% 이내인 온화한 지역에서도 계절 오염으로 출력이 20% 넘게 떨어질 수 있으며, 여름철 ±31일 창 안에 연 1회 최적 세척을 하면 이익이 최대 3.6% 늘었다(Micheli et al., Energy 2021). | E22: ScienceDirect는 403. Semantic Scholar 초록으로 확인. 초록은 '연 3% 이내'라고만 하고 2.8%는 본문 미확인. 세척 창은 '31일'이 아니라 '±31일'. | F22: https://www.sciencedirect.com/science/article/abs/pii/S0360544220321253
A23: 태양광 | B23: 부분 확인 | C23: (사례) SunEdison(Golnas & Voss, IEEE PVSC 2012): 인버터가 티켓 빈도·에너지 손실 모두 1위(2차 문헌 인용: 티켓 43%, 손실 36%). 에너지 손실의 50%가 사건 5%에서 발생(장기 정지). 27개월 미실현 발전량은 총 발전의 약 1%. | D23: SunEdison(Golnas & Voss): 인버터가 이슈 빈도와 에너지 손실 비중 모두 1위였고, 에너지 손실의 50%가 사건의 5%(장기 정지)에서 발생했으며, 27개월 미실현 발전량은 총 발전의 약 1%였다. | E23: 슬라이드 막대그래프에는 수치 라벨이 없어 '티켓 43%, 손실 36%'는 인용 URL에서 확인 불가. 2차 문헌의 서지를 따로 밝히거나 삭제해야 함. | F23: https://pdfs.semanticscholar.org/7535/1afe78f698d9c94ea6f0e48183712c19a7d5.pdf
A24: 태양광 | B24: 부분 확인 | C24: (사례) Raptor Maps(업계 보고서): 설비 기인 손실 2025년 5.08%(2021년 2.36%의 2배 이상). 손실 비중은 스트링 26.89%, 접속반 21.51%, 트래커 약 14%, 인버터 25% 미만. 연 5회 점검 사이트 약 3% vs 연 1회 약 7%. 도킹 드론 운영 사이트 평균 3%. | D24: Raptor Maps(업계 보고서): 설비 기인 손실은 2025년 5.08%(2021년 2.36%의 2배 이상)였고, 손실 비중은 스트링 26.89%, 접속반 21.51%, 트래커 약 14%, 인버터 25% 미만이었다. 연 1회 점검 사이트는 평균 약 7%, 연 5회 점검 사이트는 약 3%의 손실을 보였다(상관관계). | E24: '도킹 드론 운영 사이트 평균 3%'는 PV Tech 기사에 없음. 원 보고서에서 확인하지 못했다면 삭제해야 함. | F24: https://www.pv-tech.org/pv-project-power-loss-doubled-in-last-five-years-raptor-maps/
A25: 태양광 | B25: 부분 확인 | C25: (사례) Universidad de Jaén 등(Micheli et al., Energy 2021): 연 오염 손실 2.8%에서도 최적화 세척으로 이익 최대 3.6% 증가. 여름 31일 창 안에서 세척하면 수익성이 있음. | D25: Universidad de Jaén(Micheli et al., Energy 2021): 스페인 남부 1MW 설비(연 오염 손실 3% 이내 지역)에서 여름철 ±31일 창 안에 연 1회 최적 세척하면 이익이 최대 3.6% 늘었다. | E25: 초록 기준. 2.8%는 본문 미확인이고, 창은 '±31일'. | F25: https://www.sciencedirect.com/science/article/abs/pii/S0360544220321253
A26: 태양광 | B26: 부분 확인 | C26: (AI효과) 비가역 열화율 추정(RdTools YoY)과 기술별·보증 대비 벤치마크: NREL PV Fleet 중앙 PLR −0.75%/yr, 서늘한 기후 −0.48, 더운 기후 −0.88%/yr(Jordan et al. 2022). YoY 방식은 센서 드리프트·데이터 이동·오염에도 강건하다(Jordan et al. 2018). | D26: NREL PV Fleet(7.2GW, 1,700개 사이트) PLR −0.75%/yr, 서늘한 기후 −0.48%/yr, 더운 기후 −0.88%/yr(Jordan et al. 2022). YoY 방식의 강건성(Jordan et al. 2018)은 본 검증에서 원문을 확인하지 못했다. 또한 NREL FY24 보고서는 CODS로 오염을 제외하면 열화율이 평균 약 −0.5%/yr라고 한다. | E26: PLR 수치는 확인. Jordan 2018 강건성 주장은 출처 URL이 없어 미확인. 오염이 PLR에 섞인다는 점(NREL 88769)도 함께 적어야 함. | F26: https://www.osti.gov/pages/biblio/1864619
... A320: 상용 사례 | B320: 검증 | C320: (AI효과) 다음날 발전량 예측: 중부발전·제이케이코어 발전량 예측 정확도 99%(정의 미공개, 2026 보도). KETEP 2026 과제: 미세먼지 반영 예측정확도 95% 이상 목표. | D320: 원문 그대로 유지(KETEP 과제 원문은 '미세먼지(soiling) 영향 포함 예측 정확도 95% 이상'). | E320: 한국경제 2026.2.19에서 99%, rndcircle 과제 공고에서 95% 목표 확인. soiling은 엄밀히 '표면 오염'이라 '미세먼지'와 같은 개념은 아니다. 99% 정확도는 지표 정의가 없어 국내 예측제도 오차율 8%와 직접 비교할 수 없다. | F320: https://app.rndcircle.io/gov-grant/5f1bfc5f-45c2-485f-b78e-e2a19ca5b61e

Sheet 출처
A1: 출처 목록
A2: '주기·수명' 번호는 설계수명·법정 점검·분석항목×주기·정기 리포트·개선항목 시트의 [n]과 대응합니다. '가평 P&ID·…' 119행은 실제 사업 도면 조사(부산물 산소·폐열회수·수처리·감압과 버퍼·외부 반입)의 출처이며, 번호는 영역별로 따로 매겨져 있습니다.
A3: 주식회사 퍼스트씨앤디 · 작성일 2026. 09. 17
A5: 구분 | B5: 번호 | C5: 제목 | D5: URL
A6: 주기·수명 | B6: 1 | C6: Jordan & Kurtz, Photovoltaic Degradation Rates — An Analytical Review | D6: https://www.osti.gov/biblio/1073525
A7: 주기·수명 | B7: 2 | C7: Jordan et al., Compendium of Photovoltaic Degradation Rates (NREL) | D7: https://research-hub.nrel.gov/en/publications/compendium-of-photovoltaic-degradation-rates-2
A8: 주기·수명 | B8: 3 | C8: NREL, Availability and Performance Loss Factors for U.S. PV Fleet Systems (FY24) | D8: https://docs.nlr.gov/docs/fy24osti/88769.pdf
A9: 주기·수명 | B9: 4 | C9: IEA PVPS T13-22:2021 Assessment of Performance Loss Rate of PV Power Systems | D9: https://iea-pvps.org/wp-content/uploads/2021/04/IEA-PVPS-T13-22_2021-Assessment-of-Performance-Loss-Rate-of-PV-Power-Systems-report.pdf
A10: 주기·수명 | B10: 5 | C10: RdTools 문서(degradation_year_on_year, soiling_srr) | D10: https://rdtools.readthedocs.io/en/stable/ / https://rdtools.readthedocs.io/en/stable/generated/rdtools.soiling.soiling_srr.html
A11: 주기·수명 | B11: 6 | C11: IEA PVPS T13-21:2022 Soiling Losses(한국어 번역본) | D11: https://iea-pvps.org/wp-content/uploads/2023/01/Korean-Translation-Report-IEA-PVPS-T13-21_2022-Soiling-Losses.pdf
A12: 주기·수명 | B12: 7 | C12: Ilse et al. 2019, Techno-Economic Assessment of Soiling Losses (Joule) | D12: https://www.cell.com/joule/fulltext/S2542-4351(19)30422-2
A13: 주기·수명 | B13: 8 | C13: NREL, Best Practices for O&M of PV and Energy Storage Systems, 3rd Ed. | D13: https://docs.nlr.gov/docs/fy19osti/73822.pdf
A14: 주기·수명 | B14: 9 | C14: SolarPower Europe, O&M Best Practice Guidelines v6.0(공식 페이지 / PDF 사본) | D14: https://www.solarpowereurope.org/insights/thematic-reports/operation-and-maintenance-best-practice-guidelines-version-6-0-1 / https://oie.rs/wp-content/uploads/2025/02/SolarPower-Europe-OM-Best-Practices-Guidelines-1-1.pdf
A15: 주기·수명 | B15: 10 | C15: Solar Best Practices – Key Performance Indicators | D15: https://solarbestpractices.com/guidelines/detail/key-performance-indicators
A16: 주기·수명 | B16: 11 | C16: Solar Best Practices – AM Guidelines v2 Technical Asset Management(보고) | D16: https://solarbestpractices.com/guidelines/detail/technical-asset-management-2
... A61: 주기·수명 | B61: 56 | C61: 기동정지 열화 리뷰(Applied Energy 2018) / OCV 조건 막 분해 성능저하(J. Power Sources) | D61: https://www.sciencedirect.com/science/article/abs/pii/S030626191830607X / https://www.sciencedirect.com/science/article/abs/pii/S0378775308021587
A62: 태양광 | C62: Jordan et al. (2022) Photovoltaic fleet degradation insights, Progress in Photovoltaics (OSTI) | D62: https://www.osti.gov/pages/biblio/1864619
A63: 태양광 | C63: Jordan et al. (2018) Robust PV Degradation Methodology and Application, IEEE JPV (OSTI) | D63: https://www.osti.gov/pages/biblio/1417794
A64: 태양광 | C64: RdTools documentation (YoY degradation, clear-sky, SRR/CODS soiling, availability) | D64: https://rdtools.readthedocs.io/en/stable/
A65: 태양광 | C65: IEA PVPS T13-21:2022 Soiling Losses Executive Summary | D65: https://iea-pvps.org/wp-content/uploads/2023/01/IEA-PVPS-T13-21-2022-EXEC-SUMM-Soiling-Losses-PV-Plants.pdf
A66: 태양광 | C66: IEA PVPS T13-30:2025 Degradation and Failure Modes in New PV Cell and Module Technologies (Executive Summary) | D66: https://iea-pvps.org/wp-content/uploads/2025/02/IEA-PVPS-T13-30-2025-EX-SUMM-Degradation-and-Failure.pdf
A67: 태양광 | C67: IEA PVPS T13-10:2018 Review on Infrared and Electroluminescence Imaging for PV Field Applications | D67: https://iea-pvps.org/wp-content/uploads/2020/01/Review_on_IR_and_EL_Imaging_for_PV_Field_Applications_by_Task_13.pdf
A68: 태양광 | C68: IEA PVPS T13-24:2021 Qualification of PV Power Plants using Mobile Test Equipment | D68: https://iea-pvps.org/wp-content/uploads/2021/04/IEA-PVPS-T13-24_2021_Qualification-of-PV-Power-Plants_report.pdf
A69: 태양광 | C69: IEC TS 62446-3:2017 Outdoor infrared thermography (IEC webstore) | D69: https://webstore.iec.ch/en/publication/28628
A70: 태양광 | C70: PVEducation - Effect of Temperature | D70: https://www.pveducation.org/pvcdrom/solar-cell-operation/effect-of-temperature
A71: 태양광 | C71: Sera et al. On the Perturb-and-Observe and Incremental Conductance MPPT Methods for PV Systems (IEEE JPV / Aalborg Univ.) | D71: https://vbn.aau.dk/en/publications/on-the-perturb-and-observe-and-incremental-conductance-mppt-metho/
A72: 태양광 | C72: NREL - A Primer on the Unintentional Islanding Protection | D72: https://docs.nrel.gov/docs/fy22osti/77782.pdf
A73: 태양광 | C73: NREL - IEEE 1547-2018 anti-islanding evaluation | D73: https://www2.nrel.gov/grid/ieee-standard-1547/anti-islanding
... A490: 상용 사례 | C490: 산업통상자원부 - 수소 안전관리 로드맵 2.0(2023.5, 법무법인 세종 배포본) | D490: http://www.shinkim.com/newsletter/2023/GA/2023_vol185/links/2023_vol185_102.pdf
A491: 가평 P&ID·부산물 산소 | B491: 1 | C491: Panchawadkar, D. — Review of Opportunities to Valorise the Oxygen Generated from Water Electrolysis (KTH 석사논문, 2024) | D491: http://www.diva-portal.org/smash/get/diva2:1901182/FULLTEXT01.pdf
A492: 가평 P&ID·부산물 산소 | B492: 2 | C492: NexantECA — Making money out of thin air: Valorizing the oxygen byproduct of green hydrogen production | D492: https://www.nexanteca.com/blog/making-money-out-thin-air-valorizing-oxygen-byproduct-green-hydrogen-production
A493: 가평 P&ID·부산물 산소 | B493: 3 | C493: IRENA — Sale of electrolysis by-products (oxygen and heat), Innovation Landscape for Smart Electrification | D493: https://www.irena.org/Innovation-landscape-for-smart-electrification/Power-to-hydrogen/30-Sale-of-electrolysis-by-products-oxygen-and-heat
A494: 가평 P&ID·부산물 산소 | B494: 4 | C494: EIGA Doc 04/26 — Fire Hazards of Oxygen and Oxygen-Enriched Atmospheres | D494: https://www.eiga.eu/uploads/documents/DOC004.pdf
A495: 가평 P&ID·부산물 산소 | B495: 5 | C495: AIGA 021/20 — Oxygen Pipeline and Piping Systems (EIGA Doc 13/20 · CGA G-4.4 국제공통본) | D495: https://asiaiga.org/uploaded_docs/en_AIGA_21_20_Oxygen_Pipeline_and_Piping_Systems.pdf
A496: 가평 P&ID·부산물 산소 | B496: 6 | C496: 고압가스 안전관리법 시행규칙 [별표 4] — 고압가스 제조의 시설·기술·검사·감리 및 정밀안전검진 기준 | D496: https://www.law.go.kr/LSW/flDownload.do?flSeq=51958249
A497: 가평 P&ID·부산물 산소 | B497: 7 | C497: 고압가스 안전관리법 시행규칙 [별표 1] — 저장능력 산정기준 | D497: https://www.law.go.kr/LSW//flDownload.do?gubun=&flSeq=116031027&bylClsCd=110201
A498: 가평 P&ID·부산물 산소 | B498: 8 | C498: 고압가스 안전관리법 시행규칙 제2조 (정의) — 국가법령정보센터 | D498: https://www.law.go.kr/LSW/lsInfoP.do?urlMode=lsInfoP&lsId=006285
A499: 가평 P&ID·부산물 산소 | B499: 9 | C499: 산업안전보건기준에 관한 규칙 제618조 (정의) | D499: https://www.law.go.kr/%EB%B2%95%EB%A0%B9/%EC%82%B0%EC%97%85%EC%95%88%EC%A0%84%EB%B3%B4%EA%B1%B4%EA%B8%B0%EC%A4%80%EC%97%90%EA%B4%80%ED%95%9C%EA%B7%9C%EC%B9%99/%EC%A0%9C618%EC%A1%B0
A500: 가평 P&ID·부산물 산소 | B500: 10 | C500: 물가자료 2024년 1월호 — 가스(공업실험용) 가격표 (조사기간 2023.12.1~12.10) | D500: https://files-scs.pstatic.net/2024/01/19/u5Kz1gEmxH/%EC%82%B0%EC%86%8C.pdf
A501: 가평 P&ID·부산물 산소 | B501: 11 | C501: 가스신문 — [초점] 용기에 충전된 산소·질소가격 어느 정도가 적정한가 (2024.1.8) | D501: https://www.gasnews.com/news/articleView.html?idxno=113645
...

Sheet 가평 사이트
A1: 가평 2MW 청정수소발전 — 도면 적용 결과 (FCND-GP-PID-002 REV.2)
A2: 고객사가 보낸 실제 사업 도면을 그대로 넣은 결과입니다. 설비 17개를 도면 명판대로 등록했고, 계장 태그 10점은 계측 항목에 바로 매핑했으며, 나머지 52행(필수 37·권장 15)은 미설치라 데이터 계약 요청 목록이 됩니다. 명판의 '미확인'은 추정값으로 채우지 않고 그대로 남긴 값이며, 그 자체가 벤더·설계사 회신 대기 목록입니다.
A3: 주식회사 퍼스트씨앤디 · 작성일 2026. 09. 17
A5: 구분 | B5: 코드·태그 | C5: 이름·계측 항목 | D5: 명판 · 설비·한정자 | E5: 주기 | F5: 상태·중요도
A6: 설비 트리 | B6: 코드 | C6: 이름 | D6: 명판 (도면 표기 그대로 · 미확인은 그대로 남긴다) | F6: 중요도
A7: 설비 | B7: PV1 | C7: 태양광 발전설비 | D7: dc kwp 1,500 (미확인: ac kw) | F7: 4
A8: 설비 | B8: ESS1 | C8: ESS 설비 | D8: energy kwh 2,000 (미확인: power kw, chemistry) | F8: 4
A9: 설비 | B9: ELZ1 | C9: PEM 수전해 설비 | D9: rated kw 2,500 · technology PEM · h2 rated kg h 44.9 · outlet bar 30 (미확인: nm3 reference c) | F9: 5
A10: 설비 | B10: ELZ1/RECT1 | C10: 정류기 | D10: rated dc kw 2,500 (미확인: rated ac kva) | F10: 4
A11: 설비 | B11: ELZ1/WTU1 | C11: 순수 제조설비 | D11: capacity l h 500 · feed m3 h 0.5 · recycle m3 h 0.3 (미확인: recycle source) | F11: 4
A12: 설비 | B12: ELZ1/WTU1/TANK1 | C12: DI 물탱크 | D12: volume m3 20 (미확인: material, vent filter) | F12: 3
A13: 설비 | B13: H2BUF1 | C13: 수소 버퍼탱크 | D13: tank count 1 · water volume l 50,000 · max bar 30 (미확인: usable kg, pressure basis, min outlet bar) | F13: 5
A14: 설비 | B14: H2BUF1/TANK1 | C14: 버퍼 용기 | D14: water volume l 50,000 · max bar 30 (미확인: vessel type) | F14: 5
A15: 설비 | B15: PRV1 | C15: 수소 감압밸브 스키드 | D15: inlet bar max 30 · outlet bar set 0.8 (미확인: stages, class ac, class sg, min dp bar, downstream volume m3) | F15: 5
A16: 설비 | B16: FC1 | C16: PEM 연료전지 발전설비 | D16: rated kw 2,000 · technology PEMFC | F16: 5
A17: 설비 | B17: FC1/HX1 | C17: 폐열회수 열교환기 HX-301 | D17: duty kw 350 (미확인: type, wall type, plate material, design approach k, design ua kw k) | F17: 4
... A23: 설비 | B23: H2DLV1 | C23: 외부 수소 반입 설비 | D23: (미확인: design bar, meter type, meter accuracy pct, bank present, vent stack) | F23: 5
A24: 도면 계장 태그 | B24: 태그 | C24: 계측 항목 | D24: 설비 · 한정자 | E24: 주기 | F24: 상태
A25: 계장 | B25: FT-101 | C25: 정제수 급수 유량 [water.flow.feed] | D25: ELZ1/WTU1 | E25: 60초 | F25: 매핑 완료
A26: 계장 | B26: FT-201 | C26: 수소 질량유량 [h2.flow.mass] | D26: ELZ1 · elz.out | E26: 60초 | F26: 매핑 완료
A27: 계장 | B27: FT-301 | C27: 연료전지 수소 소비 유량 [fc.h2.consumption] | D27: FC1 | E27: 60초 | F27: 매핑 완료
A28: 계장 | B28: LT-101 | C28: 물탱크 수위 [water.tank.level] | D28: ELZ1/WTU1/TANK1 | E28: 60초 | F28: 매핑 완료
A29: 계장 | B29: PT-201 | C29: 수소 압력 [h2.pressure] | D29: H2BUF1 · buffer | E29: 60초 | F29: 매핑 완료
A30: 계장 | B30: PT-202 | C30: 수소 압력 [h2.pressure] | D30: FC1 · fc.inlet | E30: 60초 | F30: 매핑 완료
A31: 계장 | B31: PT-401 | C31: 저장용기 압력 [tank.pressure] | D31: O2P1/TANK1 · o2 | E31: 10초 | F31: 매핑 완료
